Workbook

Sheet 交易记录
A1: 股票 | B1: 日期 | C1: 买入价 | D1: 买入份额 | E1: 目标售价 | F1: 预期盈利 | G1: 实现份数 | H1: 实现比例 | I1: 实现盈利 | J1: 卖出日期 | K1: 完成 | L1: 买入月份 | M1: 卖出月份 | N1: 买入金额 | O1: 卖出金额 | P1: 提前卖的买价 | R1: 累计买入
A2: 柳工 | B2: 46050 | C2: 11.48 | D2: =IF(C2="","",FLOOR(6000/C2,100)) | E2: 11.98 | F2: =IF(AND(C2<>"",D2<>""),(E2-C2)*D2,"") | G2: 500 | H2: =IF(G2="","",G2/D2) | I2: =IF(H2="","",H2*F2) | J2: 46080 | K2: =IF(H2=1,1,"") | L2: =TEXT(B2,"yyyy-mm") | M2: =IF(J2="","",TEXT(J2,"yyyy-mm")) | N2: =IF(D2="","",C2*D2) | O2: =IF(D2="","",E2*G2)
A3: 柳工 | B3: 46090 | C3: 10.31 | D3: 700 | E3: =IF(C3="","",IF(A3="柳工",C3+0.57,IF(A3="三一重工",C3+1.07,IF(OR(A3="安道麦A",A3="奥佳华"),C3+0.37,C3)))) | F3: =IF(AND(C3<>"",D3<>""),(E3-C3)*D3,"") | H3: =IF(G3="","",G3/D3) | I3: =IF(H3="","",H3*F3) | J3: =IF(G3<>"",TODAY(),"") | K3: =IF(H3=1,1,"") | L3: =TEXT(B3,"yyyy-mm") | M3: =IF(J3="","",TEXT(J3,"yyyy-mm")) | N3: =IF(D3="","",C3*D3) | O3: =IF(D3="","",E3*G3)
A4: 柳工 | B4: 46090 | C4: 10.41 | D4: 600 | E4: =IF(C4="","",IF(A4="柳工",C4+0.57,IF(A4="三一重工",C4+1.07,IF(OR(A4="安道麦A",A4="奥佳华"),C4+0.37,C4)))) | F4: =IF(AND(C4<>"",D4<>""),(E4-C4)*D4,"") | H4: =IF(G4="","",G4/D4) | I4: =IF(H4="","",H4*F4) | J4: =IF(G4<>"",TODAY(),"") | K4: =IF(H4=1,1,"") | L4: =TEXT(B4,"yyyy-mm") | M4: =IF(J4="","",TEXT(J4,"yyyy-mm")) | N4: =IF(D4="","",C4*D4) | O4: =IF(D4="","",E4*G4)
A5: 柳工 | B5: 46090 | C5: 10.51 | D5: 900 | E5: =IF(C5="","",IF(A5="柳工",C5+0.57,IF(A5="三一重工",C5+1.07,IF(OR(A5="安道麦A",A5="奥佳华"),C5+0.37,C5)))) | F5: =IF(AND(C5<>"",D5<>""),(E5-C5)*D5,"") | H5: =IF(G5="","",G5/D5) | I5: =IF(H5="","",H5*F5) | J5: =IF(G5<>"",TODAY(),"") | K5: =IF(H5=1,1,"") | L5: =TEXT(B5,"yyyy-mm") | M5: =IF(J5="","",TEXT(J5,"yyyy-mm")) | N5: =IF(D5="","",C5*D5) | O5: =IF(D5="","",E5*G5)
A6: 柳工 | B6: 46090 | C6: 10.6 | D6: 700 | E6: 11.18 | F6: =IF(AND(C6<>"",D6<>""),(E6-C6)*D6,"") | H6: =IF(G6="","",G6/D6) | I6: =IF(H6="","",H6*F6) | J6: =IF(G6<>"",TODAY(),"") | K6: =IF(H6=1,1,"") | L6: =TEXT(B6,"yyyy-mm") | M6: =IF(J6="","",TEXT(J6,"yyyy-mm")) | N6: =IF(D6="","",C6*D6) | O6: =IF(D6="","",E6*G6)
A7: 柳工 | B7: 46090 | C7: 10.71 | D7: 1000 | E7: =IF(C7="","",IF(A7="柳工",C7+0.57,IF(A7="三一重工",C7+1.07,IF(OR(A7="安道麦A",A7="奥佳华"),C7+0.37,C7)))) | F7: =IF(AND(C7<>"",D7<>""),(E7-C7)*D7,"") | H7: =IF(G7="","",G7/D7) | I7: =IF(H7="","",H7*F7) | J7: =IF(G7<>"",TODAY(),"") | K7: =IF(H7=1,1,"") | L7: =TEXT(B7,"yyyy-mm") | M7: =IF(J7="","",TEXT(J7,"yyyy-mm")) | N7: =IF(D7="","",C7*D7) | O7: =IF(D7="","",E7*G7)
A8: 柳工 | B8: 46090 | C8: 10.81 | D8: =IF(C8="","",FLOOR(6000/C8,100)) | E8: =IF(C8="","",IF(A8="柳工",C8+0.57,IF(A8="三一重工",C8+1.07,IF(OR(A8="安道麦A",A8="奥佳华"),C8+0.37,C8)))) | F8: =IF(AND(C8<>"",D8<>""),(E8-C8)*D8,"") | H8: =IF(G8="","",G8/D8) | I8: =IF(H8="","",H8*F8) | J8: =IF(G8<>"",TODAY(),"") | K8: =IF(H8=1,1,"") | L8: =TEXT(B8,"yyyy-mm") | M8: =IF(J8="","",TEXT(J8,"yyyy-mm")) | N8: =IF(D8="","",C8*D8) | O8: =IF(D8="","",E8*G8)
A9: 柳工 | B9: 46090 | C9: 10.89 | D9: =IF(C9="","",FLOOR(6000/C9,100)) | E9: 11.48 | F9: =IF(AND(C9<>"",D9<>""),(E9-C9)*D9,"") | H9: =IF(G9="","",G9/D9) | I9: =IF(H9="","",H9*F9) | K9: =IF(H9=1,1,"") | L9: =TEXT(B9,"yyyy-mm") | N9: =IF(D9="","",C9*D9) | O9: =IF(D9="","",E9*G9)
A10: 安道麦 | B10: 46092 | C10: 5.91 | D10: =IF(C10="","",FLOOR(6000/C10,100)) | E10: 6.331 | F10: =IF(AND(C10<>"",D10<>""),(E10-C10)*D10,"") | G10: 1000 | H10: =IF(G10="","",G10/D10) | I10: 416 | J10: 46093 | K10: =IF(H10=1,1,"") | L10: =TEXT(B10,"yyyy-mm") | M10: =IF(J10="","",TEXT(J10,"yyyy-mm")) | N10: =IF(D10="","",C10*D10) | O10: =IF(D10="","",E10*G10)
A11: 柳工 | B11: 46097 | C11: 10.09 | D11: 800 | E11: 10.68 | F11: =IF(AND(C11<>"",D11<>""),(E11-C11)*D11,"") | H11: =IF(G11="","",G11/D11) | I11: =IF(H11="","",H11*F11) | J11: =IF(G11<>"",TODAY(),"") | K11: =IF(H11=1,1,"") | L11: =TEXT(B11,"yyyy-mm") | M11: =IF(J11="","",TEXT(J11,"yyyy-mm")) | N11: =IF(D11="","",C11*D11) | O11: =IF(D11="","",E11*G11)
A12: 柳工 | B12: 46097 | C12: 10.18 | D12: 700 | E12: 10.78 | F12: =IF(AND(C12<>"",D12<>""),(E12-C12)*D12,"") | H12: =IF(G12="","",G12/D12) | I12: =IF(H12="","",H12*F12) | J12: =IF(G12<>"",TODAY(),"") | K12: =IF(H12=1,1,"") | L12: =TEXT(B12,"yyyy-mm") | M12: =IF(J12="","",TEXT(J12,"yyyy-mm")) | N12: =IF(D12="","",C12*D12) | O12: =IF(D12="","",E12*G12)
A13: 三一重工 | B13: 46097 | C13: 20.97 | D13: 500 | E13: 21.78 | F13: =IF(AND(C13<>"",D13<>""),(E13-C13)*D13,"") | G13: 500 | H13: =IF(G13="","",G13/D13) | I13: =IF(H13="","",H13*F13) | J13: 46153 | K13: =IF(H13=1,1,"") | L13: =TEXT(B13,"yyyy-mm") | M13: =IF(J13="","",TEXT(J13,"yyyy-mm")) | N13: =IF(D13="","",C13*D13) | O13: =IF(D13="","",E13*G13)
A14: 三一重工 | B14: 46097 | C14: 21 | D14: 500 | E14: 21.68 | F14: =IF(AND(C14<>"",D14<>""),(E14-C14)*D14,"") | G14: 500 | H14: =IF(G14="","",G14/D14) | I14: =IF(H14="","",H14*F14) | J14: 46153 | K14: =IF(H14=1,1,"") | L14: =TEXT(B14,"yyyy-mm") | M14: =IF(J14="","",TEXT(J14,"yyyy-mm")) | N14: =IF(D14="","",C14*D14) | O14: =IF(D14="","",E14*G14)
A15: 三一重工 | B15: 46097 | C15: 21.03 | D15: 500 | E15: 21.55 | F15: =IF(AND(C15<>"",D15<>""),(E15-C15)*D15,"") | G15: 500 | H15: =IF(G15="","",G15/D15) | I15: =IF(H15="","",H15*F15) | J15: 46153 | K15: =IF(H15=1,1,"") | L15: =TEXT(B15,"yyyy-mm") | M15: =IF(J15="","",TEXT(J15,"yyyy-mm")) | N15: =IF(D15="","",C15*D15) | O15: =IF(D15="","",E15*G15)
A16: 柳工 | B16: 46101 | C16: 9.61 | D16: 200 | E16: 10.68 | F16: =IF(AND(C16<>"",D16<>""),(E16-C16)*D16,"") | H16: =IF(G16="","",G16/D16) | I16: =IF(H16="","",H16*F16) | J16: =IF(G16<>"",TODAY(),"") | K16: =IF(H16=1,1,"") | L16: =TEXT(B16,"yyyy-mm") | M16: =IF(J16="","",TEXT(J16,"yyyy-mm")) | N16: =IF(D16="","",C16*D16) | O16: =IF(D16="","",E16*G16)
A17: 柳工 | B17: 46105 | C17: 9.16 | D17: 600 | E17: 9.98 | F17: =IF(AND(C17<>"",D17<>""),(E17-C17)*D17,"") | G17: 600 | H17: =IF(G17="","",G17/D17) | I17: =IF(H17="","",H17*F17) | J17: 46148 | K17: =IF(H17=1,1,"") | L17: =TEXT(B17,"yyyy-mm") | M17: =IF(J17="","",TEXT(J17,"yyyy-mm")) | N17: =IF(D17="","",C17*D17) | O17: =IF(D17="","",E17*G17) | R17: 卖出
A18: 三一重工 | B18: 46136 | C18: 19.98 | D18: 200 | E18: 20.98 | F18: =IF(AND(C18<>"",D18<>""),(E18-C18)*D18,"") | G18: 200 | H18: =IF(G18="","",G18/D18) | I18: =IF(H18="","",H18*F18) | J18: 46148 | K18: =IF(H18=1,1,"") | L18: =TEXT(B18,"yyyy-mm") | M18: =IF(J18="","",TEXT(J18,"yyyy-mm")) | N18: =IF(D18="","",C18*D18) | O18: =IF(D18="","",E18*G18)
A19: 三一重工 | B19: 46140 | C19: 19.53 | D19: 500 | E19: 20.98 | F19: =IF(AND(C19<>"",D19<>""),(E19-C19)*D19,"") | G19: 500 | H19: =IF(G19="","",G19/D19) | I19: =IF(H19="","",H19*F19) | J19: 46148 | K19: =IF(H19=1,1,"") | L19: =TEXT(B19,"yyyy-mm") | M19: =IF(J19="","",TEXT(J19,"yyyy-mm")) | N19: =IF(D19="","",C19*D19) | O19: =IF(D19="","",E19*G19)
A20: 奥佳华 | B20: 46149 | C20: 5.73 | D20: 1800 | E20: 6.03 | F20: =IF(AND(C20<>"",D20<>""),(E20-C20)*D20,"") | G20: 1800 | H20: =IF(G20="","",G20/D20) | I20: =IF(H20="","",H20*F20) | J20: 46258 | K20: =IF(H20=1,1,"") | L20: =TEXT(B20,"yyyy-mm") | M20: =IF(J20="","",TEXT(J20,"yyyy-mm")) | N20: =IF(D20="","",C20*D20) | O20: =IF(D20="","",E20*G20)
A21: 柳工 | B21: 46150 | C21: 9.71 | D21: 800 | E21: 10.48 | F21: =IF(AND(C21<>"",D21<>""),(E21-C21)*D21,"") | G21: 800 | H21: =IF(G21="","",G21/D21) | I21: =IF(H21="","",H21*F21) | J21: 46153 | K21: =IF(H21=1,1,"") | L21: =TEXT(B21,"yyyy-mm") | M21: =IF(J21="","",TEXT(J21,"yyyy-mm")) | N21: =IF(D21="","",C21*D21) | O21: =IF(D21="","",E21*G21)
A22: 柳工 | B22: 46154 | C22: 9.61 | D22: =IF(C22="","",FLOOR(6000/C22,100)) | E22: 10.68 | F22: =IF(AND(C22<>"",D22<>""),(E22-C22)*D22,"") | H22: =IF(G22="","",G22/D22) | I22: =IF(H22="","",H22*F22) | J22: =IF(G22<>"",TODAY(),"") | K22: =IF(H22=1,1,"") | L22: =TEXT(B22,"yyyy-mm") | M22: =IF(J22="","",TEXT(J22,"yyyy-mm")) | N22: =IF(D22="","",C22*D22) | O22: =IF(D22="","",E22*G22) | R22: =AGGREGATE(9,6,I:I)
A23: 柳工 | B23: 46154 | C23: 9.71 | D23: 800 | E23: 10.78 | F23: =IF(AND(C23<>"",D23<>""),(E23-C23)*D23,"") | H23: =IF(G23="","",G23/D23) | I23: =IF(H23="","",H23*F23) | J23: =IF(G23<>"",TODAY(),"") | K23: =IF(H23=1,1,"") | L23: =TEXT(B23,"yyyy-mm") | M23: =IF(J23="","",TEXT(J23,"yyyy-mm")) | N23: =IF(D23="","",C23*D23) | O23: =IF(D23="","",E23*G23)
A24: 柳工 | B24: 46154 | C24: 9.81 | D24: 900 | E24: 10.88 | F24: =IF(AND(C24<>"",D24<>""),(E24-C24)*D24,"") | H24: =IF(G24="","",G24/D24) | I24: =IF(H24="","",H24*F24) | J24: =IF(G24<>"",TODAY(),"") | K24: =IF(H24=1,1,"") | L24: =TEXT(B24,"yyyy-mm") | M24: =IF(J24="","",TEXT(J24,"yyyy-mm")) | N24: =IF(D24="","",C24*D24) | O24: =IF(D24="","",E24*G24)
A25: 柳工 | B25: 46154 | C25: 9.91 | D25: 500 | E25: 10.98 | F25: =IF(AND(C25<>"",D25<>""),(E25-C25)*D25,"") | H25: =IF(G25="","",G25/D25) | I25: =IF(H25="","",H25*F25) | J25: =IF(G25<>"",TODAY(),"") | K25: =IF(H25=1,1,"") | L25: =TEXT(B25,"yyyy-mm") | M25: =IF(J25="","",TEXT(J25,"yyyy-mm")) | N25: =IF(D25="","",C25*D25) | O25: =IF(D25="","",E25*G25)
A26: 奥佳华 | B26: 46155 | C26: 5.61 | D26: 1300 | E26: 5.12 | F26: =IF(AND(C26<>"",D26<>""),(E26-C26)*D26,"") | G26: 1300 | H26: =IF(G26="","",G26/D26) | I26: =IF(H26="","",H26*F26) | J26: 46255 | K26: =IF(H26=1,1,"") | L26: =TEXT(B26,"yyyy-mm") | M26: =IF(J26="","",TEXT(J26,"yyyy-mm")) | N26: =IF(D26="","",C26*D26) | O26: =IF(D26="","",E26*G26)
A27: 柳工 | B27: 46156 | C27: 9.51 | D27: 700 | E27: =IF(C27="","",IF(A27="柳工",C27+0.57,IF(A27="三一重工",C27+1.07,IF(OR(A27="安道麦A",A27="奥佳华"),C27+0.37,C27)))) | F27: =IF(AND(C27<>"",D27<>""),(E27-C27)*D27,"") | H27: =IF(G27="","",G27/D27) | I27: =IF(H27="","",H27*F27) | J27: =IF(G27<>"",TODAY(),"") | K27: =IF(H27=1,1,"") | L27: =TEXT(B27,"yyyy-mm") | M27: =IF(J27="","",TEXT(J27,"yyyy-mm")) | N27: =IF(D27="","",C27*D27) | O27: =IF(D27="","",E27*G27) | R27: 实际盈利
A28: 三一重工 | B28: 46156 | C28: 20.81 | D28: 600 | E28: =IF(C28="","",IF(A28="柳工",C28+0.57,IF(A28="三一重工",C28+1.07,IF(OR(A28="安道麦A",A28="奥佳华"),C28+0.37,C28)))) | F28: =IF(AND(C28<>"",D28<>""),(E28-C28)*D28,"") | H28: =IF(G28="","",G28/D28) | I28: =IF(H28="","",H28*F28) | J28: =IF(G28<>"",TODAY(),"") | K28: =IF(H28=1,1,"") | L28: =TEXT(B28,"yyyy-mm") | M28: =IF(J28="","",TEXT(J28,"yyyy-mm")) | N28: =IF(D28="","",C28*D28) | O28: =IF(D28="","",E28*G28)
A29: 三一重工 | B29: 46156 | C29: 20.91 | D29: 600 | E29: =IF(C29="","",IF(A29="柳工",C29+0.57,IF(A29="三一重工",C29+1.07,IF(OR(A29="安道麦A",A29="奥佳华"),C29+0.37,C29)))) | F29: =IF(AND(C29<>"",D29<>""),(E29-C29)*D29,"") | H29: =IF(G29="","",G29/D29) | I29: =IF(H29="","",H29*F29) | J29: =IF(G29<>"",TODAY(),"") | K29: =IF(H29=1,1,"") | L29: =TEXT(B29,"yyyy-mm") | M29: =IF(J29="","",TEXT(J29,"yyyy-mm")) | N29: =IF(D29="","",C29*D29) | O29: =IF(D29="","",E29*G29)
A30: 奥佳华 | B30: 46156 | C30: 5.51 | D30: =IF(C30="","",FLOOR(6000/C30,100)) | E30: 5.34 | F30: =IF(AND(C30<>"",D30<>""),(E30-C30)*D30,"") | G30: 1000 | H30: =IF(G30="","",G30/D30) | I30: =IF(H30="","",H30*F30) | J30: 46260 | K30: =IF(H30=1,1,"") | L30: =TEXT(B30,"yyyy-mm") | M30: =IF(J30="","",TEXT(J30,"yyyy-mm")) | N30: =IF(D30="","",C30*D30) | O30: =IF(D30="","",E30*G30)
A31: 三一重工 | B31: 46160 | C31: 19.54 | D31: 100 | E31: 21.58 | F31: =IF(AND(C31<>"",D31<>""),(E31-C31)*D31,"") | H31: =IF(G31="","",G31/D31) | I31: =IF(H31="","",H31*F31) | J31: =IF(G31<>"",TODAY(),"") | K31: =IF(H31=1,1,"") | L31: =TEXT(B31,"yyyy-mm") | M31: =IF(J31="","",TEXT(J31,"yyyy-mm")) | N31: =IF(D31="","",C31*D31) | O31: =IF(D31="","",E31*G31)
A32: 三一重工 | B32: 46160 | C32: 20.01 | D32: 600 | E32: 21.58 | F32: =IF(AND(C32<>"",D32<>""),(E32-C32)*D32,"") | H32: =IF(G32="","",G32/D32) | I32: =IF(H32="","",H32*F32) | J32: =IF(G32<>"",TODAY(),"") | K32: =IF(H32=1,1,"") | L32: =TEXT(B32,"yyyy-mm") | M32: =IF(J32="","",TEXT(J32,"yyyy-mm")) | N32: =IF(D32="","",C32*D32) | O32: =IF(D32="","",E32*G32)
A33: 柳工 | B33: 46185 | C33: 8.21 | D33: 600 | E33: 8.79 | F33: =IF(AND(C33<>"",D33<>""),(E33-C33)*D33,"") | G33: 600 | H33: =IF(G33="","",G33/D33) | I33: =IF(H33="","",H33*F33) | J33: 46232 | K33: =IF(H33=1,1,"") | L33: =TEXT(B33,"yyyy-mm") | M33: =IF(J33="","",TEXT(J33,"yyyy-mm")) | N33: =IF(D33="","",C33*D33) | O33: =IF(D33="","",E33*G33)
A34: 柳工 | B34: 46190 | C34: 8.16 | D34: =IF(C34="","",FLOOR(6000/C34,100)) | E34: 8.89 | F34: =IF(AND(C34<>"",D34<>""),(E34-C34)*D34,"") | G34: 700 | H34: =IF(G34="","",G34/D34) | I34: =IF(H34="","",H34*F34) | J34: 46232 | K34: =IF(H34=1,1,"") | L34: =TEXT(B34,"yyyy-mm") | M34: =IF(J34="","",TEXT(J34,"yyyy-mm")) | N34: =IF(D34="","",C34*D34) | O34: =IF(D34="","",E34*G34)
A35: 柳工 | B35: 46195 | C35: 7.86 | D35: 600 | E35: 8.58 | F35: =IF(AND(C35<>"",D35<>""),(E35-C35)*D35,"") | G35: 600 | H35: =IF(G35="","",G35/D35) | I35: =IF(H35="","",H35*F35) | J35: 46226 | K35: =IF(H35=1,1,"") | L35: =TEXT(B35,"yyyy-mm") | M35: =IF(J35="","",TEXT(J35,"yyyy-mm")) | N35: =IF(D35="","",C35*D35) | O35: =IF(D35="","",E35*G35) | R35: =SUM(F:F,#REF!)
A36: 三一重工 | B36: 46197 | C36: 17.86 | D36: =IF(C36="","",FLOOR(6000/C36,100)) | E36: 19.38 | F36: =IF(AND(C36<>"",D36<>""),(E36-C36)*D36,"") | G36: 300 | H36: =IF(G36="","",G36/D36) | I36: =IF(H36="","",H36*F36) | J36: 46210 | K36: =IF(H36=1,1,"") | L36: =TEXT(B36,"yyyy-mm") | M36: =IF(J36="","",TEXT(J36,"yyyy-mm")) | N36: =IF(D36="","",C36*D36) | O36: =IF(D36="","",E36*G36)
A37: 三一重工 | B37: 46211 | C37: 19.01 | D37: =IF(C37="","",FLOOR(6000/C37,100)) | E37: 20.48 | F37: =IF(AND(C37<>"",D37<>""),(E37-C37)*D37,"") | G37: 300 | H37: =IF(G37="","",G37/D37) | I37: =IF(H37="","",H37*F37) | J37: 46232 | K37: =IF(H37=1,1,"") | L37: =TEXT(B37,"yyyy-mm") | M37: =IF(J37="","",TEXT(J37,"yyyy-mm")) | N37: =IF(D37="","",C37*D37) | O37: =IF(D37="","",E37*G37)
A38: 三一重工 | B38: 46212 | C38: 18.21 | D38: 100 | E38: 19.48 | F38: =IF(AND(C38<>"",D38<>""),(E38-C38)*D38,"") | G38: 100 | H38: =IF(G38="","",G38/D38) | I38: =IF(H38="","",H38*F38) | J38: 46223 | K38: =IF(H38=1,1,"") | L38: =TEXT(B38,"yyyy-mm") | M38: =IF(J38="","",TEXT(J38,"yyyy-mm")) | N38: =IF(D38="","",C38*D38) | O38: =IF(D38="","",E38*G38)
A39: 柳工 | B39: 46238 | C39: 8.51 | D39: 600 | E39: =IF(C39="","",IF(A39="柳工",C39+0.57,IF(A39="三一重工",C39+1.07,IF(OR(A39="安道麦A",A39="奥佳华"),C39+0.37,C39)))) | F39: =IF(AND(C39<>"",D39<>""),(E39-C39)*D39,"") | H39: =IF(G39="","",G39/D39) | I39: =IF(H39="","",H39*F39) | J39: =IF(G39<>"",TODAY(),"") | K39: =IF(H39=1,1,"") | L39: =TEXT(B39,"yyyy-mm") | M39: =IF(J39="","",TEXT(J39,"yyyy-mm")) | N39: =IF(D39="","",C39*D39) | O39: =IF(D39="","",E39*G39) | R39: =SUM(O:O,O36)
A40: 三一重工 | B40: 46238 | C40: 19.51 | D40: =IF(C40="","",FLOOR(6000/C40,100)) | E40: 20.78 | F40: =IF(AND(C40<>"",D40<>""),(E40-C40)*D40,"") | G40: 300 | H40: =IF(G40="","",G40/D40) | I40: =IF(H40="","",H40*F40) | J40: 46233 | K40: =IF(H40=1,1,"") | L40: =TEXT(B40,"yyyy-mm") | M40: =IF(J40="","",TEXT(J40,"yyyy-mm")) | N40: =IF(D40="","",C40*D40) | O40: =IF(D40="","",E40*G40)
...

Sheet 按列查看
A1: 股票 | B1: 日期 | C1: 买入价 | D1: 买入份额 | E1: 目标售价 | F1: 预期盈利 | G1: 实现份数 | H1: 实现比例 | I1: 实现盈利 | J1: 卖出日期 | K1: 完成 | L1: 买入月份 | M1: 卖出月份 | N1: 买入金额 | O1: 卖出金额 | P1: 列1 | Q1: 列2 | R1: 列3 | S1: 列4 | T1: 列5 | U1: 列6 | V1: 列7 | W1: 列8 | X1: 列9 | Y1: 列10 | Z1: 列11
A2: {=_xlfn.SORTBY(_xlfn._xlws.FILTER(交易记录!A2:O499,交易记录!A2:A499<>""),MATCH(_xlfn._xlws.FILTER(交易记录!A2:A499,交易记录!A2:A499<>""),交易记录!A2:A499,0),TRUE,_xlfn._xlws.FILTER(交易记录!C2:C499,交易记录!A2:A499<>""),TRUE)}

Sheet 工作表1
A1: 完成 | B1: （全部）
A2: 完成 | B2: （全部）
A4: 行标签 | B4: 求和项：实现盈利 | C4: 求和项：买入份额 | D4: 求和项：实现份数
A5: 安道麦A | B5: 416 | C5: 1000 | D5: 1000 | H5: 46092 | N5: 总计
A6: 46092 | B6: 416 | C6: 1000 | D6: 1000 | G6: 求和项：实现份数 | H6: 求和项：实现盈利 | I6: 求和项：买入份额 | J6: 求和项：实现份数 | K6: 求和项：实现盈利 | L6: 求和项：买入份额 | M6: 求和项：实现份数 | N6: 求和项：实现盈利 | O6: 求和项：买入份额 | P6: 求和项：实现份数
A7: 5.91 | B7: 416 | C7: 1000 | D7: 1000 | H7: 416 | I7: 1000 | J7: 1000 | N7: 416 | O7: 1000 | P7: 1000
A8: 柳工 | B8: 1358 | C8: 8500 | D8: 1900 | H8: 416 | I8: 1000 | J8: 1000 | N8: 416 | O8: 1000 | P8: 1000
A9: 46050 | B9: 250 | C9: 500 | D9: 500 | G9: 0 | N9: 250 | O9: 5400 | P9: 500
A10: 11.48 | B10: 250 | C10: 500 | D10: 500 | G10: 0 | N10: 0 | O10: 700 | P10: 0
A11: 46090 | B11: 0 | C11: 4900 | D11: 0 | G11: 0 | N11: 0 | O11: 600 | P11: 0
A12: 10.31 | B12: 0 | C12: 700 | D12: 0 | G12: 0 | N12: 0 | O12: 900 | P12: 0
A13: 10.41 | B13: 0 | C13: 600 | D13: 0 | G13: 0 | N13: 0 | O13: 700 | P13: 0
A14: 10.51 | B14: 0 | C14: 900 | D14: 0 | G14: 0 | N14: 0 | O14: 1000 | P14: 0
A15: 10.6 | B15: 0 | C15: 700 | D15: 0 | G15: 0 | N15: 0 | O15: 500 | P15: 0
A16: 10.71 | B16: 0 | C16: 1000 | D16: 0 | G16: 0 | N16: 0 | O16: 500 | P16: 0
A17: 10.81 | B17: 0 | C17: 500 | D17: 0 | N17: 250 | O17: 500 | P17: 500
A18: 10.89 | B18: 0 | C18: 500 | D18: 0 | K18: 0 | L18: 0 | M18: 0 | N18: 0 | O18: 0 | P18: 0
A19: 46097 | B19: 0 | C19: 1500 | D19: 0 | K19: 0 | L19: 0 | M19: 0 | N19: 0 | O19: 0 | P19: 0
A20: 10.18 | B20: 0 | C20: 700 | D20: 0 | G20: 0 | H20: 416 | I20: 1000 | J20: 1000 | K20: 0 | L20: 0 | M20: 0 | N20: 666 | O20: 6400 | P20: 1500
A21: 10.09 | B21: 0 | C21: 800 | D21: 0
A22: 46101 | B22: 0 | C22: 200 | D22: 0
A23: 9.61 | B23: 0 | C23: 200 | D23: 0
A24: 46105 | B24: 492 | C24: 600 | D24: 600
A25: 9.16 | B25: 492 | C25: 600 | D25: 600
A26: 46150 | B26: 616 | C26: 800 | D26: 800
A27: 9.71 | B27: 616 | C27: 800 | D27: 800
A28: 46154 | B28: 0 | C28: 0 | D28: 0
B29: 0 | C29: 0 | D29: 0
A30: 三一重工 | B30: 1930 | C30: 2200 | D30: 2200
A31: 46097 | B31: 1005 | C31: 1500 | D31: 1500
A32: 21.03 | B32: 260 | C32: 500 | D32: 500
A33: 21 | B33: 340 | C33: 500 | D33: 500
A34: 20.97 | B34: 405 | C34: 500 | D34: 500
A35: 46136 | B35: 200 | C35: 200 | D35: 200
A36: 19.98 | B36: 200 | C36: 200 | D36: 200
A37: 46140 | B37: 725 | C37: 500 | D37: 500
A38: 19.53 | B38: 725 | C38: 500 | D38: 500
A39: 奥佳华 | B39: 0 | C39: 1800 | D39: 0
A40: 46149 | B40: 0 | C40: 1800 | D40: 0
A41: 5.73 | B41: 0 | C41: 1800 | D41: 0
...

Sheet 26日历视图
A1: 2026 | B1: 1 | C1: 2 | D1: 3 | E1: 4 | F1: 5 | G1: 6 | H1: 7 | I1: 8 | J1: 9 | K1: 10 | L1: 11 | M1: 12
A2: 1 | B2: =_xlfn.LET(_xlpm.当前日期,DATE($A$1,B$1,$A2),_xlpm.买入次数,COUNTIF(交易记录!$B$2:$B$998,_xlpm.当前日期),_xlpm.买入股数,SUMIF(交易记录!$B$2:$B$998,_xlpm.当前日期,交易记录!$D$2:$D$998),_xlpm.卖出次数,COUNTIF(交易记录!$J$2:$J$998,_xlpm.当前日期),_xlpm.卖出股数,SUMIF(交易记录!$J$2:$J$998,_xlpm.当前日期,交易记录!$G$2:$G$998),_xlpm.盈利,SUMIF(交易记录!$J$2:$J$998,_xlpm.当前日期,交易记录!$I$2:$I$998),_xlpm.买入文本,IF(_xlpm.买入次数>0,"买入"&_xlpm.买入次数&"次，共"&_xlpm.买入股数&"股",""),_xlpm.卖出文本,IF(_xlpm.卖出次数>0,"卖出"&_xlpm.卖出次数&"次，共"&_xlpm.卖出股数&"股",""),_xlpm.盈利文本,IF(_xlpm.盈利>0,"实现盈利"&TEXT(_xlpm.盈利,"0.00")&"元",""),_xlpm.结果,_xlfn.TEXTJOIN(CHAR(10),TRUE,_xlpm.买入文本,_xlpm.卖出文本,_xlpm.盈利文本),IF(_xlpm.结果="","",_xlpm.结果)) | C2: =_xlfn.LET(_xlpm.当前日期,DATE($A$1,C$1,$A2),_xlpm.买入次数,COUNTIF(交易记录!$B$2:$B$998,_xlpm.当前日期),_xlpm.买入股数,SUMIF(交易记录!$B$2:$B$998,_xlpm.当前日期,交易记录!$D$2:$D$998),_xlpm.卖出次数,COUNTIF(交易记录!$J$2:$J$998,_xlpm.当前日期),_xlpm.卖出股数,SUMIF(交易记录!$J$2:$J$998,_xlpm.当前日期,交易记录!$G$2:$G$998),_xlpm.盈利,SUMIF(交易记录!$J$2:$J$998,_xlpm.当前日期,交易记录!$I$2:$I$998),_xlpm.买入文本,IF(_xlpm.买入次数>0,"买入"&_xlpm.买入次数&"次，共"&_xlpm.买入股数&"股",""),_xlpm.卖出文本,IF(_xlpm.卖出次数>0,"卖出"&_xlpm.卖出次数&"次，共"&_xlpm.卖出股数&"股",""),_xlpm.盈利文本,IF(_xlpm.盈利>0,"实现盈利"&TEXT(_xlpm.盈利,"0.00")&"元",""),_xlpm.结果,_xlfn.TEXTJOIN(CHAR(10),TRUE,_xlpm.买入文本,_xlpm.卖出文本,_xlpm.盈利文本),IF(_xlpm.结果="","",_xlpm.结果)) | D2: =_xlfn.LET(_xlpm.当前日期,DATE($A$1,D$1,$A2),_xlpm.买入次数,COUNTIF(交易记录!$B$2:$B$998,_xlpm.当前日期),_xlpm.买入股数,SUMIF(交易记录!$B$2:$B$998,_xlpm.当前日期,交易记录!$D$2:$D$998),_xlpm.卖出次数,COUNTIF(交易记录!$J$2:$J$998,_xlpm.当前日期),_xlpm.卖出股数,SUMIF(交易记录!$J$2:$J$998,_xlpm.当前日期,交易记录!$G$2:$G$998),_xlpm.盈利,SUMIF(交易记录!$J$2:$J$998,_xlpm.当前日期,交易记录!$I$2:$I$998),_xlpm.买入文本,IF(_xlpm.买入次数>0,"买入"&_xlpm.买入次数&"次，共"&_xlpm.买入股数&"股",""),_xlpm.卖出文本,IF(_xlpm.卖出次数>0,"卖出"&_xlpm.卖出次数&"次，共"&_xlpm.卖出股数&"股",""),_xlpm.盈利文本,IF(_xlpm.盈利>0,"实现盈利"&TEXT(_xlpm.盈利,"0.00")&"元",""),_xlpm.结果,_xlfn.TEXTJOIN(CHAR(10),TRUE,_xlpm.买入文本,_xlpm.卖出文本,_xlpm.盈利文本),IF(_xlpm.结果="","",_xlpm.结果)) | E2: =_xlfn.LET(_xlpm.当前日期,DATE($A$1,E$1,$A2),_xlpm.买入次数,COUNTIF(交易记录!$B$2:$B$998,_xlpm.当前日期),_xlpm.买入股数,SUMIF(交易记录!$B$2:$B$998,_xlpm.当前日期,交易记录!$D$2:$D$998),_xlpm.卖出次数,COUNTIF(交易记录!$J$2:$J$998,_xlpm.当前日期),_xlpm.卖出股数,SUMIF(交易记录!$J$2:$J$998,_xlpm.当前日期,交易记录!$G$2:$G$998),_xlpm.盈利,SUMIF(交易记录!$J$2:$J$998,_xlpm.当前日期,交易记录!$I$2:$I$998),_xlpm.买入文本,IF(_xlpm.买入次数>0,"买入"&_xlpm.买入次数&"次，共"&_xlpm.买入股数&"股",""),_xlpm.卖出文本,IF(_xlpm.卖出次数>0,"卖出"&_xlpm.卖出次数&"次，共"&_xlpm.卖出股数&"股",""),_xlpm.盈利文本,IF(_xlpm.盈利>0,"实现盈利"&TEXT(_xlpm.盈利,"0.00")&"元",""),_xlpm.结果,_xlfn.TEXTJOIN(CHAR(10),TRUE,_xlpm.买入文本,_xlpm.卖出文本,_xlpm.盈利文本),IF(_xlpm.结果="","",_xlpm.结果)) | F2: =_xlfn.LET(_xlpm.当前日期,DATE($A$1,F$1,$A2),_xlpm.买入次数,COUNTIF(交易记录!$B$2:$B$998,_xlpm.当前日期),_xlpm.买入股数,SUMIF(交易记录!$B$2:$B$998,_xlpm.当前日期,交易记录!$D$2:$D$998),_xlpm.卖出次数,COUNTIF(交易记录!$J$2:$J$998,_xlpm.当前日期),_xlpm.卖出股数,SUMIF(交易记录!$J$2:$J$998,_xlpm.当前日期,交易记录!$G$2:$G$998),_xlpm.盈利,SUMIF(交易记录!$J$2:$J$998,_xlpm.当前日期,交易记录!$I$2:$I$998),_xlpm.买入文本,IF(_xlpm.买入次数>0,"买入"&_xlpm.买入次数&"次，共"&_xlpm.买入股数&"股",""),_xlpm.卖出文本,IF(_xlpm.卖出次数>0,"卖出"&_xlpm.卖出次数&"次，共"&_xlpm.卖出股数&"股",""),_xlpm.盈利文本,IF(_xlpm.盈利>0,"实现盈利"&TEXT(_xlpm.盈利,"0.00")&"元",""),_xlpm.结果,_xlfn.TEXTJOIN(CHAR(10),TRUE,_xlpm.买入文本,_xlpm.卖出文本,_xlpm.盈利文本),IF(_xlpm.结果="","",_xlpm.结果)) | G2: =_xlfn.LET(_xlpm.当前日期,DATE($A$1,G$1,$A2),_xlpm.买入次数,COUNTIF(交易记录!$B$2:$B$998,_xlpm.当前日期),_xlpm.买入股数,SUMIF(交易记录!$B$2:$B$998,_xlpm.当前日期,交易记录!$D$2:$D$998),_xlpm.卖出次数,COUNTIF(交易记录!$J$2:$J$998,_xlpm.当前日期),_xlpm.卖出股数,SUMIF(交易记录!$J$2:$J$998,_xlpm.当前日期,交易记录!$G$2:$G$998),_xlpm.盈利,SUMIF(交易记录!$J$2:$J$998,_xlpm.当前日期,交易记录!$I$2:$I$998),_xlpm.买入文本,IF(_xlpm.买入次数>0,"买入"&_xlpm.买入次数&"次，共"&_xlpm.买入股数&"股",""),_xlpm.卖出文本,IF(_xlpm.卖出次数>0,"卖出"&_xlpm.卖出次数&"次，共"&_xlpm.卖出股数&"股",""),_xlpm.盈利文本,IF(_xlpm.盈利>0,"实现盈利"&TEXT(_xlpm.盈利,"0.00")&"元",""),_xlpm.结果,_xlfn.TEXTJOIN(CHAR(10),TRUE,_xlpm.买入文本,_xlpm.卖出文本,_xlpm.盈利文本),IF(_xlpm.结果="","",_xlpm.结果)) | H2: =_xlfn.LET(_xlpm.当前日期,DATE($A$1,H$1,$A2),_xlpm.买入次数,COUNTIF(交易记录!$B$2:$B$998,_xlpm.当前日期),_xlpm.买入股数,SUMIF(交易记录!$B$2:$B$998,_xlpm.当前日期,交易记录!$D$2:$D$998),_xlpm.卖出次数,COUNTIF(交易记录!$J$2:$J$998,_xlpm.当前日期),_xlpm.卖出股数,SUMIF(交易记录!$J$2:$J$998,_xlpm.当前日期,交易记录!$G$2:$G$998),_xlpm.盈利,SUMIF(交易记录!$J$2:$J$998,_xlpm.当前日期,交易记录!$I$2:$I$998),_xlpm.买入文本,IF(_xlpm.买入次数>0,"买入"&_xlpm.买入次数&"次，共"&_xlpm.买入股数&"股",""),_xlpm.卖出文本,IF(_xlpm.卖出次数>0,"卖出"&_xlpm.卖出次数&"次，共"&_xlpm.卖出股数&"股",""),_xlpm.盈利文本,IF(_xlpm.盈利>0,"实现盈利"&TEXT(_xlpm.盈利,"0.00")&"元",""),_xlpm.结果,_xlfn.TEXTJOIN(CHAR(10),TRUE,_xlpm.买入文本,_xlpm.卖出文本,_xlpm.盈利文本),IF(_xlpm.结果="","",_xlpm.结果)) | I2: =_xlfn.LET(_xlpm.当前日期,DATE($A$1,I$1,$A2),_xlpm.买入次数,COUNTIF(交易记录!$B$2:$B$998,_xlpm.当前日期),_xlpm.买入股数,SUMIF(交易记录!$B$2:$B$998,_xlpm.当前日期,交易记录!$D$2:$D$998),_xlpm.卖出次数,COUNTIF(交易记录!$J$2:$J$998,_xlpm.当前日期),_xlpm.卖出股数,SUMIF(交易记录!$J$2:$J$998,_xlpm.当前日期,交易记录!$G$2:$G$998),_xlpm.盈利,SUMIF(交易记录!$J$2:$J$998,_xlpm.当前日期,交易记录!$I$2:$I$998),_xlpm.买入文本,IF(_xlpm.买入次数>0,"买入"&_xlpm.买入次数&"次，共"&_xlpm.买入股数&"股",""),_xlpm.卖出文本,IF(_xlpm.卖出次数>0,"卖出"&_xlpm.卖出次数&"次，共"&_xlpm.卖出股数&"股",""),_xlpm.盈利文本,IF(_xlpm.盈利>0,"实现盈利"&TEXT(_xlpm.盈利,"0.00")&"元",""),_xlpm.结果,_xlfn.TEXTJOIN(CHAR(10),TRUE,_xlpm.买入文本,_xlpm.卖出文本,_xlpm.盈利文本),IF(_xlpm.结果="","",_xlpm.结果)) | ... M2: =_xlfn.LET(_xlpm.当前日期,DATE($A$1,M$1,$A2),_xlpm.买入次数,COUNTIF(交易记录!$B$2:$B$998,_xlpm.当前日期),_xlpm.买入股数,SUMIF(交易记录!$B$2:$B$998,_xlpm.当前日期,交易记录!$D$2:$D$998),_xlpm.卖出次数,COUNTIF(交易记录!$J$2:$J$998,_xlpm.当前日期),_xlpm.卖出股数,SUMIF(交易记录!$J$2:$J$998,_xlpm.当前日期,交易记录!$G$2:$G$998),_xlpm.盈利,SUMIF(交易记录!$J$2:$J$998,_xlpm.当前日期,交易记录!$I$2:$I$998),_xlpm.买入文本,IF(_xlpm.买入次数>0,"买入"&_xlpm.买入次数&"次，共"&_xlpm.买入股数&"股",""),_xlpm.卖出文本,IF(_xlpm.卖出次数>0,"卖出"&_xlpm.卖出次数&"次，共"&_xlpm.卖出股数&"股",""),_xlpm.盈利文本,IF(_xlpm.盈利>0,"实现盈利"&TEXT(_xlpm.盈利,"0.00")&"元",""),_xlpm.结果,_xlfn.TEXTJOIN(CHAR(10),TRUE,_xlpm.买入文本,_xlpm.卖出文本,_xlpm.盈利文本),IF(_xlpm.结果="","",_xlpm.结果))
A3: 2 | B3: =_xlfn.LET(_xlpm.当前日期,DATE($A$1,B$1,$A3),_xlpm.买入次数,COUNTIF(交易记录!$B$2:$B$998,_xlpm.当前日期),_xlpm.买入股数,SUMIF(交易记录!$B$2:$B$998,_xlpm.当前日期,交易记录!$D$2:$D$998),_xlpm.卖出次数,COUNTIF(交易记录!$J$2:$J$998,_xlpm.当前日期),_xlpm.卖出股数,SUMIF(交易记录!$J$2:$J$998,_xlpm.当前日期,交易记录!$G$2:$G$998),_xlpm.盈利,SUMIF(交易记录!$J$2:$J$998,_xlpm.当前日期,交易记录!$I$2:$I$998),_xlpm.买入文本,IF(_xlpm.买入次数>0,"买入"&_xlpm.买入次数&"次，共"&_xlpm.买入股数&"股",""),_xlpm.卖出文本,IF(_xlpm.卖出次数>0,"卖出"&_xlpm.卖出次数&"次，共"&_xlpm.卖出股数&"股",""),_xlpm.盈利文本,IF(_xlpm.盈利>0,"实现盈利"&TEXT(_xlpm.盈利,"0.00")&"元",""),_xlpm.结果,_xlfn.TEXTJOIN(CHAR(10),TRUE,_xlpm.买入文本,_xlpm.卖出文本,_xlpm.盈利文本),IF(_xlpm.结果="","",_xlpm.结果)) | C3: =_xlfn.LET(_xlpm.当前日期,DATE($A$1,C$1,$A3),_xlpm.买入次数,COUNTIF(交易记录!$B$2:$B$998,_xlpm.当前日期),_xlpm.买入股数,SUMIF(交易记录!$B$2:$B$998,_xlpm.当前日期,交易记录!$D$2:$D$998),_xlpm.卖出次数,COUNTIF(交易记录!$J$2:$J$998,_xlpm.当前日期),_xlpm.卖出股数,SUMIF(交易记录!$J$2:$J$998,_xlpm.当前日期,交易记录!$G$2:$G$998),_xlpm.盈利,SUMIF(交易记录!$J$2:$J$998,_xlpm.当前日期,交易记录!$I$2:$I$998),_xlpm.买入文本,IF(_xlpm.买入次数>0,"买入"&_xlpm.买入次数&"次，共"&_xlpm.买入股数&"股",""),_xlpm.卖出文本,IF(_xlpm.卖出次数>0,"卖出"&_xlpm.卖出次数&"次，共"&_xlpm.卖出股数&"股",""),_xlpm.盈利文本,IF(_xlpm.盈利>0,"实现盈利"&TEXT(_xlpm.盈利,"0.00")&"元",""),_xlpm.结果,_xlfn.TEXTJOIN(CHAR(10),TRUE,_xlpm.买入文本,_xlpm.卖出文本,_xlpm.盈利文本),IF(_xlpm.结果="","",_xlpm.结果)) | D3: =_xlfn.LET(_xlpm.当前日期,DATE($A$1,D$1,$A3),_xlpm.买入次数,COUNTIF(交易记录!$B$2:$B$998,_xlpm.当前日期),_xlpm.买入股数,SUMIF(交易记录!$B$2:$B$998,_xlpm.当前日期,交易记录!$D$2:$D$998),_xlpm.卖出次数,COUNTIF(交易记录!$J$2:$J$998,_xlpm.当前日期),_xlpm.卖出股数,SUMIF(交易记录!$J$2:$J$998,_xlpm.当前日期,交易记录!$G$2:$G$998),_xlpm.盈利,SUMIF(交易记录!$J$2:$J$998,_xlpm.当前日期,交易记录!$I$2:$I$998),_xlpm.买入文本,IF(_xlpm.买入次数>0,"买入"&_xlpm.买入次数&"次，共"&_xlpm.买入股数&"股",""),_xlpm.卖出文本,IF(_xlpm.卖出次数>0,"卖出"&_xlpm.卖出次数&"次，共"&_xlpm.卖出股数&"股",""),_xlpm.盈利文本,IF(_xlpm.盈利>0,"实现盈利"&TEXT(_xlpm.盈利,"0.00")&"元",""),_xlpm.结果,_xlfn.TEXTJOIN(CHAR(10),TRUE,_xlpm.买入文本,_xlpm.卖出文本,_xlpm.盈利文本),IF(_xlpm.结果="","",_xlpm.结果)) | E3: =_xlfn.LET(_xlpm.当前日期,DATE($A$1,E$1,$A3),_xlpm.买入次数,COUNTIF(交易记录!$B$2:$B$998,_xlpm.当前日期),_xlpm.买入股数,SUMIF(交易记录!$B$2:$B$998,_xlpm.当前日期,交易记录!$D$2:$D$998),_xlpm.卖出次数,COUNTIF(交易记录!$J$2:$J$998,_xlpm.当前日期),_xlpm.卖出股数,SUMIF(交易记录!$J$2:$J$998,_xlpm.当前日期,交易记录!$G$2:$G$998),_xlpm.盈利,SUMIF(交易记录!$J$2:$J$998,_xlpm.当前日期,交易记录!$I$2:$I$998),_xlpm.买入文本,IF(_xlpm.买入次数>0,"买入"&_xlpm.买入次数&"次，共"&_xlpm.买入股数&"股",""),_xlpm.卖出文本,IF(_xlpm.卖出次数>0,"卖出"&_xlpm.卖出次数&"次，共"&_xlpm.卖出股数&"股",""),_xlpm.盈利文本,IF(_xlpm.盈利>0,"实现盈利"&TEXT(_xlpm.盈利,"0.00")&"元",""),_xlpm.结果,_xlfn.TEXTJOIN(CHAR(10),TRUE,_xlpm.买入文本,_xlpm.卖出文本,_xlpm.盈利文本),IF(_xlpm.结果="","",_xlpm.结果)) | F3: =_xlfn.LET(_xlpm.当前日期,DATE($A$1,F$1,$A3),_xlpm.买入次数,COUNTIF(交易记录!$B$2:$B$998,_xlpm.当前日期),_xlpm.买入股数,SUMIF(交易记录!$B$2:$B$998,_xlpm.当前日期,交易记录!$D$2:$D$998),_xlpm.卖出次数,COUNTIF(交易记录!$J$2:$J$998,_xlpm.当前日期),_xlpm.卖出股数,SUMIF(交易记录!$J$2:$J$998,_xlpm.当前日期,交易记录!$G$2:$G$998),_xlpm.盈利,SUMIF(交易记录!$J$2:$J$998,_xlpm.当前日期,交易记录!$I$2:$I$998),_xlpm.买入文本,IF(_xlpm.买入次数>0,"买入"&_xlpm.买入次数&"次，共"&_xlpm.买入股数&"股",""),_xlpm.卖出文本,IF(_xlpm.卖出次数>0,"卖出"&_xlpm.卖出次数&"次，共"&_xlpm.卖出股数&"股",""),_xlpm.盈利文本,IF(_xlpm.盈利>0,"实现盈利"&TEXT(_xlpm.盈利,"0.00")&"元",""),_xlpm.结果,_xlfn.TEXTJOIN(CHAR(10),TRUE,_xlpm.买入文本,_xlpm.卖出文本,_xlpm.盈利文本),IF(_xlpm.结果="","",_xlpm.结果)) | G3: =_xlfn.LET(_xlpm.当前日期,DATE($A$1,G$1,$A3),_xlpm.买入次数,COUNTIF(交易记录!$B$2:$B$998,_xlpm.当前日期),_xlpm.买入股数,SUMIF(交易记录!$B$2:$B$998,_xlpm.当前日期,交易记录!$D$2:$D$998),_xlpm.卖出次数,COUNTIF(交易记录!$J$2:$J$998,_xlpm.当前日期),_xlpm.卖出股数,SUMIF(交易记录!$J$2:$J$998,_xlpm.当前日期,交易记录!$G$2:$G$998),_xlpm.盈利,SUMIF(交易记录!$J$2:$J$998,_xlpm.当前日期,交易记录!$I$2:$I$998),_xlpm.买入文本,IF(_xlpm.买入次数>0,"买入"&_xlpm.买入次数&"次，共"&_xlpm.买入股数&"股",""),_xlpm.卖出文本,IF(_xlpm.卖出次数>0,"卖出"&_xlpm.卖出次数&"次，共"&_xlpm.卖出股数&"股",""),_xlpm.盈利文本,IF(_xlpm.盈利>0,"实现盈利"&TEXT(_xlpm.盈利,"0.00")&"元",""),_xlpm.结果,_xlfn.TEXTJOIN(CHAR(10),TRUE,_xlpm.买入文本,_xlpm.卖出文本,_xlpm.盈利文本),IF(_xlpm.结果="","",_xlpm.结果)) | H3: =_xlfn.LET(_xlpm.当前日期,DATE($A$1,H$1,$A3),_xlpm.买入次数,COUNTIF(交易记录!$B$2:$B$998,_xlpm.当前日期),_xlpm.买入股数,SUMIF(交易记录!$B$2:$B$998,_xlpm.当前日期,交易记录!$D$2:$D$998),_xlpm.卖出次数,COUNTIF(交易记录!$J$2:$J$998,_xlpm.当前日期),_xlpm.卖出股数,SUMIF(交易记录!$J$2:$J$998,_xlpm.当前日期,交易记录!$G$2:$G$998),_xlpm.盈利,SUMIF(交易记录!$J$2:$J$998,_xlpm.当前日期,交易记录!$I$2:$I$998),_xlpm.买入文本,IF(_xlpm.买入次数>0,"买入"&_xlpm.买入次数&"次，共"&_xlpm.买入股数&"股",""),_xlpm.卖出文本,IF(_xlpm.卖出次数>0,"卖出"&_xlpm.卖出次数&"次，共"&_xlpm.卖出股数&"股",""),_xlpm.盈利文本,IF(_xlpm.盈利>0,"实现盈利"&TEXT(_xlpm.盈利,"0.00")&"元",""),_xlpm.结果,_xlfn.TEXTJOIN(CHAR(10),TRUE,_xlpm.买入文本,_xlpm.卖出文本,_xlpm.盈利文本),IF(_xlpm.结果="","",_xlpm.结果)) | I3: =_xlfn.LET(_xlpm.当前日期,DATE($A$1,I$1,$A3),_xlpm.买入次数,COUNTIF(交易记录!$B$2:$B$998,_xlpm.当前日期),_xlpm.买入股数,SUMIF(交易记录!$B$2:$B$998,_xlpm.当前日期,交易记录!$D$2:$D$998),_xlpm.卖出次数,COUNTIF(交易记录!$J$2:$J$998,_xlpm.当前日期),_xlpm.卖出股数,SUMIF(交易记录!$J$2:$J$998,_xlpm.当前日期,交易记录!$G$2:$G$998),_xlpm.盈利,SUMIF(交易记录!$J$2:$J$998,_xlpm.当前日期,交易记录!$I$2:$I$998),_xlpm.买入文本,IF(_xlpm.买入次数>0,"买入"&_xlpm.买入次数&"次，共"&_xlpm.买入股数&"股",""),_xlpm.卖出文本,IF(_xlpm.卖出次数>0,"卖出"&_xlpm.卖出次数&"次，共"&_xlpm.卖出股数&"股",""),_xlpm.盈利文本,IF(_xlpm.盈利>0,"实现盈利"&TEXT(_xlpm.盈利,"0.00")&"元",""),_xlpm.结果,_xlfn.TEXTJOIN(CHAR(10),TRUE,_xlpm.买入文本,_xlpm.卖出文本,_xlpm.盈利文本),IF(_xlpm.结果="","",_xlpm.结果)) | ... M3: =_xlfn.LET(_xlpm.当前日期,DATE($A$1,M$1,$A3),_xlpm.买入次数,COUNTIF(交易记录!$B$2:$B$998,_xlpm.当前日期),_xlpm.买入股数,SUMIF(交易记录!$B$2:$B$998,_xlpm.当前日期,交易记录!$D$2:$D$998),_xlpm.卖出次数,COUNTIF(交易记录!$J$2:$J$998,_xlpm.当前日期),_xlpm.卖出股数,SUMIF(交易记录!$J$2:$J$998,_xlpm.当前日期,交易记录!$G$2:$G$998),_xlpm.盈利,SUMIF(交易记录!$J$2:$J$998,_xlpm.当前日期,交易记录!$I$2:$I$998),_xlpm.买入文本,IF(_xlpm.买入次数>0,"买入"&_xlpm.买入次数&"次，共"&_xlpm.买入股数&"股",""),_xlpm.卖出文本,IF(_xlpm.卖出次数>0,"卖出"&_xlpm.卖出次数&"次，共"&_xlpm.卖出股数&"股",""),_xlpm.盈利文本,IF(_xlpm.盈利>0,"实现盈利"&TEXT(_xlpm.盈利,"0.00")&"元",""),_xlpm.结果,_xlfn.TEXTJOIN(CHAR(10),TRUE,_xlpm.买入文本,_xlpm.卖出文本,_xlpm.盈利文本),IF(_xlpm.结果="","",_xlpm.结果))
A4: 3 | B4: =_xlfn.LET(_xlpm.当前日期,DATE($A$1,B$1,$A4),_xlpm.买入次数,COUNTIF(交易记录!$B$2:$B$998,_xlpm.当前日期),_xlpm.买入股数,SUMIF(交易记录!$B$2:$B$998,_xlpm.当前日期,交易记录!$D$2:$D$998),_xlpm.卖出次数,COUNTIF(交易记录!$J$2:$J$998,_xlpm.当前日期),_xlpm.卖出股数,SUMIF(交易记录!$J$2:$J$998,_xlpm.当前日期,交易记录!$G$2:$G$998),_xlpm.盈利,SUMIF(交易记录!$J$2:$J$998,_xlpm.当前日期,交易记录!$I$2:$I$998),_xlpm.买入文本,IF(_xlpm.买入次数>0,"买入"&_xlpm.买入次数&"次，共"&_xlpm.买入股数&"股",""),_xlpm.卖出文本,IF(_xlpm.卖出次数>0,"卖出"&_xlpm.卖出次数&"次，共"&_xlpm.卖出股数&"股",""),_xlpm.盈利文本,IF(_xlpm.盈利>0,"实现盈利"&TEXT(_xlpm.盈利,"0.00")&"元",""),_xlpm.结果,_xlfn.TEXTJOIN(CHAR(10),TRUE,_xlpm.买入文本,_xlpm.卖出文本,_xlpm.盈利文本),IF(_xlpm.结果="","",_xlpm.结果)) | C4: =_xlfn.LET(_xlpm.当前日期,DATE($A$1,C$1,$A4),_xlpm.买入次数,COUNTIF(交易记录!$B$2:$B$998,_xlpm.当前日期),_xlpm.买入股数,SUMIF(交易记录!$B$2:$B$998,_xlpm.当前日期,交易记录!$D$2:$D$998),_xlpm.卖出次数,COUNTIF(交易记录!$J$2:$J$998,_xlpm.当前日期),_xlpm.卖出股数,SUMIF(交易记录!$J$2:$J$998,_xlpm.当前日期,交易记录!$G$2:$G$998),_xlpm.盈利,SUMIF(交易记录!$J$2:$J$998,_xlpm.当前日期,交易记录!$I$2:$I$998),_xlpm.买入文本,IF(_xlpm.买入次数>0,"买入"&_xlpm.买入次数&"次，共"&_xlpm.买入股数&"股",""),_xlpm.卖出文本,IF(_xlpm.卖出次数>0,"卖出"&_xlpm.卖出次数&"次，共"&_xlpm.卖出股数&"股",""),_xlpm.盈利文本,IF(_xlpm.盈利>0,"实现盈利"&TEXT(_xlpm.盈利,"0.00")&"元",""),_xlpm.结果,_xlfn.TEXTJOIN(CHAR(10),TRUE,_xlpm.买入文本,_xlpm.卖出文本,_xlpm.盈利文本),IF(_xlpm.结果="","",_xlpm.结果)) | D4: =_xlfn.LET(_xlpm.当前日期,DATE($A$1,D$1,$A4),_xlpm.买入次数,COUNTIF(交易记录!$B$2:$B$998,_xlpm.当前日期),_xlpm.买入股数,SUMIF(交易记录!$B$2:$B$998,_xlpm.当前日期,交易记录!$D$2:$D$998),_xlpm.卖出次数,COUNTIF(交易记录!$J$2:$J$998,_xlpm.当前日期),_xlpm.卖出股数,SUMIF(交易记录!$J$2:$J$998,_xlpm.当前日期,交易记录!$G$2:$G$998),_xlpm.盈利,SUMIF(交易记录!$J$2:$J$998,_xlpm.当前日期,交易记录!$I$2:$I$998),_xlpm.买入文本,IF(_xlpm.买入次数>0,"买入"&_xlpm.买入次数&"次，共"&_xlpm.买入股数&"股",""),_xlpm.卖出文本,IF(_xlpm.卖出次数>0,"卖出"&_xlpm.卖出次数&"次，共"&_xlpm.卖出股数&"股",""),_xlpm.盈利文本,IF(_xlpm.盈利>0,"实现盈利"&TEXT(_xlpm.盈利,"0.00")&"元",""),_xlpm.结果,_xlfn.TEXTJOIN(CHAR(10),TRUE,_xlpm.买入文本,_xlpm.卖出文本,_xlpm.盈利文本),IF(_xlpm.结果="","",_xlpm.结果)) | E4: =_xlfn.LET(_xlpm.当前日期,DATE($A$1,E$1,$A4),_xlpm.买入次数,COUNTIF(交易记录!$B$2:$B$998,_xlpm.当前日期),_xlpm.买入股数,SUMIF(交易记录!$B$2:$B$998,_xlpm.当前日期,交易记录!$D$2:$D$998),_xlpm.卖出次数,COUNTIF(交易记录!$J$2:$J$998,_xlpm.当前日期),_xlpm.卖出股数,SUMIF(交易记录!$J$2:$J$998,_xlpm.当前日期,交易记录!$G$2:$G$998),_xlpm.盈利,SUMIF(交易记录!$J$2:$J$998,_xlpm.当前日期,交易记录!$I$2:$I$998),_xlpm.买入文本,IF(_xlpm.买入次数>0,"买入"&_xlpm.买入次数&"次，共"&_xlpm.买入股数&"股",""),_xlpm.卖出文本,IF(_xlpm.卖出次数>0,"卖出"&_xlpm.卖出次数&"次，共"&_xlpm.卖出股数&"股",""),_xlpm.盈利文本,IF(_xlpm.盈利>0,"实现盈利"&TEXT(_xlpm.盈利,"0.00")&"元",""),_xlpm.结果,_xlfn.TEXTJOIN(CHAR(10),TRUE,_xlpm.买入文本,_xlpm.卖出文本,_xlpm.盈利文本),IF(_xlpm.结果="","",_xlpm.结果)) | F4: =_xlfn.LET(_xlpm.当前日期,DATE($A$1,F$1,$A4),_xlpm.买入次数,COUNTIF(交易记录!$B$2:$B$998,_xlpm.当前日期),_xlpm.买入股数,SUMIF(交易记录!$B$2:$B$998,_xlpm.当前日期,交易记录!$D$2:$D$998),_xlpm.卖出次数,COUNTIF(交易记录!$J$2:$J$998,_xlpm.当前日期),_xlpm.卖出股数,SUMIF(交易记录!$J$2:$J$998,_xlpm.当前日期,交易记录!$G$2:$G$998),_xlpm.盈利,SUMIF(交易记录!$J$2:$J$998,_xlpm.当前日期,交易记录!$I$2:$I$998),_xlpm.买入文本,IF(_xlpm.买入次数>0,"买入"&_xlpm.买入次数&"次，共"&_xlpm.买入股数&"股",""),_xlpm.卖出文本,IF(_xlpm.卖出次数>0,"卖出"&_xlpm.卖出次数&"次，共"&_xlpm.卖出股数&"股",""),_xlpm.盈利文本,IF(_xlpm.盈利>0,"实现盈利"&TEXT(_xlpm.盈利,"0.00")&"元",""),_xlpm.结果,_xlfn.TEXTJOIN(CHAR(10),TRUE,_xlpm.买入文本,_xlpm.卖出文本,_xlpm.盈利文本),IF(_xlpm.结果="","",_xlpm.结果)) | G4: =_xlfn.LET(_xlpm.当前日期,DATE($A$1,G$1,$A4),_xlpm.买入次数,COUNTIF(交易记录!$B$2:$B$998,_xlpm.当前日期),_xlpm.买入股数,SUMIF(交易记录!$B$2:$B$998,_xlpm.当前日期,交易记录!$D$2:$D$998),_xlpm.卖出次数,COUNTIF(交易记录!$J$2:$J$998,_xlpm.当前日期),_xlpm.卖出股数,SUMIF(交易记录!$J$2:$J$998,_xlpm.当前日期,交易记录!$G$2:$G$998),_xlpm.盈利,SUMIF(交易记录!$J$2:$J$998,_xlpm.当前日期,交易记录!$I$2:$I$998),_xlpm.买入文本,IF(_xlpm.买入次数>0,"买入"&_xlpm.买入次数&"次，共"&_xlpm.买入股数&"股",""),_xlpm.卖出文本,IF(_xlpm.卖出次数>0,"卖出"&_xlpm.卖出次数&"次，共"&_xlpm.卖出股数&"股",""),_xlpm.盈利文本,IF(_xlpm.盈利>0,"实现盈利"&TEXT(_xlpm.盈利,"0.00")&"元",""),_xlpm.结果,_xlfn.TEXTJOIN(CHAR(10),TRUE,_xlpm.买入文本,_xlpm.卖出文本,_xlpm.盈利文本),IF(_xlpm.结果="","",_xlpm.结果)) | H4: =_xlfn.LET(_xlpm.当前日期,DATE($A$1,H$1,$A4),_xlpm.买入次数,COUNTIF(交易记录!$B$2:$B$998,_xlpm.当前日期),_xlpm.买入股数,SUMIF(交易记录!$B$2:$B$998,_xlpm.当前日期,交易记录!$D$2:$D$998),_xlpm.卖出次数,COUNTIF(交易记录!$J$2:$J$998,_xlpm.当前日期),_xlpm.卖出股数,SUMIF(交易记录!$J$2:$J$998,_xlpm.当前日期,交易记录!$G$2:$G$998),_xlpm.盈利,SUMIF(交易记录!$J$2:$J$998,_xlpm.当前日期,交易记录!$I$2:$I$998),_xlpm.买入文本,IF(_xlpm.买入次数>0,"买入"&_xlpm.买入次数&"次，共"&_xlpm.买入股数&"股",""),_xlpm.卖出文本,IF(_xlpm.卖出次数>0,"卖出"&_xlpm.卖出次数&"次，共"&_xlpm.卖出股数&"股",""),_xlpm.盈利文本,IF(_xlpm.盈利>0,"实现盈利"&TEXT(_xlpm.盈利,"0.00")&"元",""),_xlpm.结果,_xlfn.TEXTJOIN(CHAR(10),TRUE,_xlpm.买入文本,_xlpm.卖出文本,_xlpm.盈利文本),IF(_xlpm.结果="","",_xlpm.结果)) | I4: =_xlfn.LET(_xlpm.当前日期,DATE($A$1,I$1,$A4),_xlpm.买入次数,COUNTIF(交易记录!$B$2:$B$998,_xlpm.当前日期),_xlpm.买入股数,SUMIF(交易记录!$B$2:$B$998,_xlpm.当前日期,交易记录!$D$2:$D$998),_xlpm.卖出次数,COUNTIF(交易记录!$J$2:$J$998,_xlpm.当前日期),_xlpm.卖出股数,SUMIF(交易记录!$J$2:$J$998,_xlpm.当前日期,交易记录!$G$2:$G$998),_xlpm.盈利,SUMIF(交易记录!$J$2:$J$998,_xlpm.当前日期,交易记录!$I$2:$I$998),_xlpm.买入文本,IF(_xlpm.买入次数>0,"买入"&_xlpm.买入次数&"次，共"&_xlpm.买入股数&"股",""),_xlpm.卖出文本,IF(_xlpm.卖出次数>0,"卖出"&_xlpm.卖出次数&"次，共"&_xlpm.卖出股数&"股",""),_xlpm.盈利文本,IF(_xlpm.盈利>0,"实现盈利"&TEXT(_xlpm.盈利,"0.00")&"元",""),_xlpm.结果,_xlfn.TEXTJOIN(CHAR(10),TRUE,_xlpm.买入文本,_xlpm.卖出文本,_xlpm.盈利文本),IF(_xlpm.结果="","",_xlpm.结果)) | ... M4: =_xlfn.LET(_xlpm.当前日期,DATE($A$1,M$1,$A4),_xlpm.买入次数,COUNTIF(交易记录!$B$2:$B$998,_xlpm.当前日期),_xlpm.买入股数,SUMIF(交易记录!$B$2:$B$998,_xlpm.当前日期,交易记录!$D$2:$D$998),_xlpm.卖出次数,COUNTIF(交易记录!$J$2:$J$998,_xlpm.当前日期),_xlpm.卖出股数,SUMIF(交易记录!$J$2:$J$998,_xlpm.当前日期,交易记录!$G$2:$G$998),_xlpm.盈利,SUMIF(交易记录!$J$2:$J$998,_xlpm.当前日期,交易记录!$I$2:$I$998),_xlpm.买入文本,IF(_xlpm.买入次数>0,"买入"&_xlpm.买入次数&"次，共"&_xlpm.买入股数&"股",""),_xlpm.卖出文本,IF(_xlpm.卖出次数>0,"卖出"&_xlpm.卖出次数&"次，共"&_xlpm.卖出股数&"股",""),_xlpm.盈利文本,IF(_xlpm.盈利>0,"实现盈利"&TEXT(_xlpm.盈利,"0.00")&"元",""),_xlpm.结果,_xlfn.TEXTJOIN(CHAR(10),TRUE,_xlpm.买入文本,_xlpm.卖出文本,_xlpm.盈利文本),IF(_xlpm.结果="","",_xlpm.结果))
A5: 4 | B5: =_xlfn.LET(_xlpm.当前日期,DATE($A$1,B$1,$A5),_xlpm.买入次数,COUNTIF(交易记录!$B$2:$B$998,_xlpm.当前日期),_xlpm.买入股数,SUMIF(交易记录!$B$2:$B$998,_xlpm.当前日期,交易记录!$D$2:$D$998),_xlpm.卖出次数,COUNTIF(交易记录!$J$2:$J$998,_xlpm.当前日期),_xlpm.卖出股数,SUMIF(交易记录!$J$2:$J$998,_xlpm.当前日期,交易记录!$G$2:$G$998),_xlpm.盈利,SUMIF(交易记录!$J$2:$J$998,_xlpm.当前日期,交易记录!$I$2:$I$998),_xlpm.买入文本,IF(_xlpm.买入次数>0,"买入"&_xlpm.买入次数&"次，共"&_xlpm.买入股数&"股",""),_xlpm.卖出文本,IF(_xlpm.卖出次数>0,"卖出"&_xlpm.卖出次数&"次，共"&_xlpm.卖出股数&"股",""),_xlpm.盈利文本,IF(_xlpm.盈利>0,"实现盈利"&TEXT(_xlpm.盈利,"0.00")&"元",""),_xlpm.结果,_xlfn.TEXTJOIN(CHAR(10),TRUE,_xlpm.买入文本,_xlpm.卖出文本,_xlpm.盈利文本),IF(_xlpm.结果="","",_xlpm.结果)) | C5: =_xlfn.LET(_xlpm.当前日期,DATE($A$1,C$1,$A5),_xlpm.买入次数,COUNTIF(交易记录!$B$2:$B$998,_xlpm.当前日期),_xlpm.买入股数,SUMIF(交易记录!$B$2:$B$998,_xlpm.当前日期,交易记录!$D$2:$D$998),_xlpm.卖出次数,COUNTIF(交易记录!$J$2:$J$998,_xlpm.当前日期),_xlpm.卖出股数,SUMIF(交易记录!$J$2:$J$998,_xlpm.当前日期,交易记录!$G$2:$G$998),_xlpm.盈利,SUMIF(交易记录!$J$2:$J$998,_xlpm.当前日期,交易记录!$I$2:$I$998),_xlpm.买入文本,IF(_xlpm.买入次数>0,"买入"&_xlpm.买入次数&"次，共"&_xlpm.买入股数&"股",""),_xlpm.卖出文本,IF(_xlpm.卖出次数>0,"卖出"&_xlpm.卖出次数&"次，共"&_xlpm.卖出股数&"股",""),_xlpm.盈利文本,IF(_xlpm.盈利>0,"实现盈利"&TEXT(_xlpm.盈利,"0.00")&"元",""),_xlpm.结果,_xlfn.TEXTJOIN(CHAR(10),TRUE,_xlpm.买入文本,_xlpm.卖出文本,_xlpm.盈利文本),IF(_xlpm.结果="","",_xlpm.结果)) | D5: =_xlfn.LET(_xlpm.当前日期,DATE($A$1,D$1,$A5),_xlpm.买入次数,COUNTIF(交易记录!$B$2:$B$998,_xlpm.当前日期),_xlpm.买入股数,SUMIF(交易记录!$B$2:$B$998,_xlpm.当前日期,交易记录!$D$2:$D$998),_xlpm.卖出次数,COUNTIF(交易记录!$J$2:$J$998,_xlpm.当前日期),_xlpm.卖出股数,SUMIF(交易记录!$J$2:$J$998,_xlpm.当前日期,交易记录!$G$2:$G$998),_xlpm.盈利,SUMIF(交易记录!$J$2:$J$998,_xlpm.当前日期,交易记录!$I$2:$I$998),_xlpm.买入文本,IF(_xlpm.买入次数>0,"买入"&_xlpm.买入次数&"次，共"&_xlpm.买入股数&"股",""),_xlpm.卖出文本,IF(_xlpm.卖出次数>0,"卖出"&_xlpm.卖出次数&"次，共"&_xlpm.卖出股数&"股",""),_xlpm.盈利文本,IF(_xlpm.盈利>0,"实现盈利"&TEXT(_xlpm.盈利,"0.00")&"元",""),_xlpm.结果,_xlfn.TEXTJOIN(CHAR(10),TRUE,_xlpm.买入文本,_xlpm.卖出文本,_xlpm.盈利文本),IF(_xlpm.结果="","",_xlpm.结果)) | E5: =_xlfn.LET(_xlpm.当前日期,DATE($A$1,E$1,$A5),_xlpm.买入次数,COUNTIF(交易记录!$B$2:$B$998,_xlpm.当前日期),_xlpm.买入股数,SUMIF(交易记录!$B$2:$B$998,_xlpm.当前日期,交易记录!$D$2:$D$998),_xlpm.卖出次数,COUNTIF(交易记录!$J$2:$J$998,_xlpm.当前日期),_xlpm.卖出股数,SUMIF(交易记录!$J$2:$J$998,_xlpm.当前日期,交易记录!$G$2:$G$998),_xlpm.盈利,SUMIF(交易记录!$J$2:$J$998,_xlpm.当前日期,交易记录!$I$2:$I$998),_xlpm.买入文本,IF(_xlpm.买入次数>0,"买入"&_xlpm.买入次数&"次，共"&_xlpm.买入股数&"股",""),_xlpm.卖出文本,IF(_xlpm.卖出次数>0,"卖出"&_xlpm.卖出次数&"次，共"&_xlpm.卖出股数&"股",""),_xlpm.盈利文本,IF(_xlpm.盈利>0,"实现盈利"&TEXT(_xlpm.盈利,"0.00")&"元",""),_xlpm.结果,_xlfn.TEXTJOIN(CHAR(10),TRUE,_xlpm.买入文本,_xlpm.卖出文本,_xlpm.盈利文本),IF(_xlpm.结果="","",_xlpm.结果)) | F5: =_xlfn.LET(_xlpm.当前日期,DATE($A$1,F$1,$A5),_xlpm.买入次数,COUNTIF(交易记录!$B$2:$B$998,_xlpm.当前日期),_xlpm.买入股数,SUMIF(交易记录!$B$2:$B$998,_xlpm.当前日期,交易记录!$D$2:$D$998),_xlpm.卖出次数,COUNTIF(交易记录!$J$2:$J$998,_xlpm.当前日期),_xlpm.卖出股数,SUMIF(交易记录!$J$2:$J$998,_xlpm.当前日期,交易记录!$G$2:$G$998),_xlpm.盈利,SUMIF(交易记录!$J$2:$J$998,_xlpm.当前日期,交易记录!$I$2:$I$998),_xlpm.买入文本,IF(_xlpm.买入次数>0,"买入"&_xlpm.买入次数&"次，共"&_xlpm.买入股数&"股",""),_xlpm.卖出文本,IF(_xlpm.卖出次数>0,"卖出"&_xlpm.卖出次数&"次，共"&_xlpm.卖出股数&"股",""),_xlpm.盈利文本,IF(_xlpm.盈利>0,"实现盈利"&TEXT(_xlpm.盈利,"0.00")&"元",""),_xlpm.结果,_xlfn.TEXTJOIN(CHAR(10),TRUE,_xlpm.买入文本,_xlpm.卖出文本,_xlpm.盈利文本),IF(_xlpm.结果="","",_xlpm.结果)) | G5: =_xlfn.LET(_xlpm.当前日期,DATE($A$1,G$1,$A5),_xlpm.买入次数,COUNTIF(交易记录!$B$2:$B$998,_xlpm.当前日期),_xlpm.买入股数,SUMIF(交易记录!$B$2:$B$998,_xlpm.当前日期,交易记录!$D$2:$D$998),_xlpm.卖出次数,COUNTIF(交易记录!$J$2:$J$998,_xlpm.当前日期),_xlpm.卖出股数,SUMIF(交易记录!$J$2:$J$998,_xlpm.当前日期,交易记录!$G$2:$G$998),_xlpm.盈利,SUMIF(交易记录!$J$2:$J$998,_xlpm.当前日期,交易记录!$I$2:$I$998),_xlpm.买入文本,IF(_xlpm.买入次数>0,"买入"&_xlpm.买入次数&"次，共"&_xlpm.买入股数&"股",""),_xlpm.卖出文本,IF(_xlpm.卖出次数>0,"卖出"&_xlpm.卖出次数&"次，共"&_xlpm.卖出股数&"股",""),_xlpm.盈利文本,IF(_xlpm.盈利>0,"实现盈利"&TEXT(_xlpm.盈利,"0.00")&"元",""),_xlpm.结果,_xlfn.TEXTJOIN(CHAR(10),TRUE,_xlpm.买入文本,_xlpm.卖出文本,_xlpm.盈利文本),IF(_xlpm.结果="","",_xlpm.结果)) | H5: =_xlfn.LET(_xlpm.当前日期,DATE($A$1,H$1,$A5),_xlpm.买入次数,COUNTIF(交易记录!$B$2:$B$998,_xlpm.当前日期),_xlpm.买入股数,SUMIF(交易记录!$B$2:$B$998,_xlpm.当前日期,交易记录!$D$2:$D$998),_xlpm.卖出次数,COUNTIF(交易记录!$J$2:$J$998,_xlpm.当前日期),_xlpm.卖出股数,SUMIF(交易记录!$J$2:$J$998,_xlpm.当前日期,交易记录!$G$2:$G$998),_xlpm.盈利,SUMIF(交易记录!$J$2:$J$998,_xlpm.当前日期,交易记录!$I$2:$I$998),_xlpm.买入文本,IF(_xlpm.买入次数>0,"买入"&_xlpm.买入次数&"次，共"&_xlpm.买入股数&"股",""),_xlpm.卖出文本,IF(_xlpm.卖出次数>0,"卖出"&_xlpm.卖出次数&"次，共"&_xlpm.卖出股数&"股",""),_xlpm.盈利文本,IF(_xlpm.盈利>0,"实现盈利"&TEXT(_xlpm.盈利,"0.00")&"元",""),_xlpm.结果,_xlfn.TEXTJOIN(CHAR(10),TRUE,_xlpm.买入文本,_xlpm.卖出文本,_xlpm.盈利文本),IF(_xlpm.结果="","",_xlpm.结果)) | I5: =_xlfn.LET(_xlpm.当前日期,DATE($A$1,I$1,$A5),_xlpm.买入次数,COUNTIF(交易记录!$B$2:$B$998,_xlpm.当前日期),_xlpm.买入股数,SUMIF(交易记录!$B$2:$B$998,_xlpm.当前日期,交易记录!$D$2:$D$998),_xlpm.卖出次数,COUNTIF(交易记录!$J$2:$J$998,_xlpm.当前日期),_xlpm.卖出股数,SUMIF(交易记录!$J$2:$J$998,_xlpm.当前日期,交易记录!$G$2:$G$998),_xlpm.盈利,SUMIF(交易记录!$J$2:$J$998,_xlpm.当前日期,交易记录!$I$2:$I$998),_xlpm.买入文本,IF(_xlpm.买入次数>0,"买入"&_xlpm.买入次数&"次，共"&_xlpm.买入股数&"股",""),_xlpm.卖出文本,IF(_xlpm.卖出次数>0,"卖出"&_xlpm.卖出次数&"次，共"&_xlpm.卖出股数&"股",""),_xlpm.盈利文本,IF(_xlpm.盈利>0,"实现盈利"&TEXT(_xlpm.盈利,"0.00")&"元",""),_xlpm.结果,_xlfn.TEXTJOIN(CHAR(10),TRUE,_xlpm.买入文本,_xlpm.卖出文本,_xlpm.盈利文本),IF(_xlpm.结果="","",_xlpm.结果)) | ... M5: =_xlfn.LET(_xlpm.当前日期,DATE($A$1,M$1,$A5),_xlpm.买入次数,COUNTIF(交易记录!$B$2:$B$998,_xlpm.当前日期),_xlpm.买入股数,SUMIF(交易记录!$B$2:$B$998,_xlpm.当前日期,交易记录!$D$2:$D$998),_xlpm.卖出次数,COUNTIF(交易记录!$J$2:$J$998,_xlpm.当前日期),_xlpm.卖出股数,SUMIF(交易记录!$J$2:$J$998,_xlpm.当前日期,交易记录!$G$2:$G$998),_xlpm.盈利,SUMIF(交易记录!$J$2:$J$998,_xlpm.当前日期,交易记录!$I$2:$I$998),_xlpm.买入文本,IF(_xlpm.买入次数>0,"买入"&_xlpm.买入次数&"次，共"&_xlpm.买入股数&"股",""),_xlpm.卖出文本,IF(_xlpm.卖出次数>0,"卖出"&_xlpm.卖出次数&"次，共"&_xlpm.卖出股数&"股",""),_xlpm.盈利文本,IF(_xlpm.盈利>0,"实现盈利"&TEXT(_xlpm.盈利,"0.00")&"元",""),_xlpm.结果,_xlfn.TEXTJOIN(CHAR(10),TRUE,_xlpm.买入文本,_xlpm.卖出文本,_xlpm.盈利文本),IF(_xlpm.结果="","",_xlpm.结果))
A6: 5 | B6: =_xlfn.LET(_xlpm.当前日期,DATE($A$1,B$1,$A6),_xlpm.买入次数,COUNTIF(交易记录!$B$2:$B$998,_xlpm.当前日期),_xlpm.买入股数,SUMIF(交易记录!$B$2:$B$998,_xlpm.当前日期,交易记录!$D$2:$D$998),_xlpm.卖出次数,COUNTIF(交易记录!$J$2:$J$998,_xlpm.当前日期),_xlpm.卖出股数,SUMIF(交易记录!$J$2:$J$998,_xlpm.当前日期,交易记录!$G$2:$G$998),_xlpm.盈利,SUMIF(交易记录!$J$2:$J$998,_xlpm.当前日期,交易记录!$I$2:$I$998),_xlpm.买入文本,IF(_xlpm.买入次数>0,"买入"&_xlpm.买入次数&"次，共"&_xlpm.买入股数&"股",""),_xlpm.卖出文本,IF(_xlpm.卖出次数>0,"卖出"&_xlpm.卖出次数&"次，共"&_xlpm.卖出股数&"股",""),_xlpm.盈利文本,IF(_xlpm.盈利>0,"实现盈利"&TEXT(_xlpm.盈利,"0.00")&"元",""),_xlpm.结果,_xlfn.TEXTJOIN(CHAR(10),TRUE,_xlpm.买入文本,_xlpm.卖出文本,_xlpm.盈利文本),IF(_xlpm.结果="","",_xlpm.结果)) | C6: =_xlfn.LET(_xlpm.当前日期,DATE($A$1,C$1,$A6),_xlpm.买入次数,COUNTIF(交易记录!$B$2:$B$998,_xlpm.当前日期),_xlpm.买入股数,SUMIF(交易记录!$B$2:$B$998,_xlpm.当前日期,交易记录!$D$2:$D$998),_xlpm.卖出次数,COUNTIF(交易记录!$J$2:$J$998,_xlpm.当前日期),_xlpm.卖出股数,SUMIF(交易记录!$J$2:$J$998,_xlpm.当前日期,交易记录!$G$2:$G$998),_xlpm.盈利,SUMIF(交易记录!$J$2:$J$998,_xlpm.当前日期,交易记录!$I$2:$I$998),_xlpm.买入文本,IF(_xlpm.买入次数>0,"买入"&_xlpm.买入次数&"次，共"&_xlpm.买入股数&"股",""),_xlpm.卖出文本,IF(_xlpm.卖出次数>0,"卖出"&_xlpm.卖出次数&"次，共"&_xlpm.卖出股数&"股",""),_xlpm.盈利文本,IF(_xlpm.盈利>0,"实现盈利"&TEXT(_xlpm.盈利,"0.00")&"元",""),_xlpm.结果,_xlfn.TEXTJOIN(CHAR(10),TRUE,_xlpm.买入文本,_xlpm.卖出文本,_xlpm.盈利文本),IF(_xlpm.结果="","",_xlpm.结果)) | D6: =_xlfn.LET(_xlpm.当前日期,DATE($A$1,D$1,$A6),_xlpm.买入次数,COUNTIF(交易记录!$B$2:$B$998,_xlpm.当前日期),_xlpm.买入股数,SUMIF(交易记录!$B$2:$B$998,_xlpm.当前日期,交易记录!$D$2:$D$998),_xlpm.卖出次数,COUNTIF(交易记录!$J$2:$J$998,_xlpm.当前日期),_xlpm.卖出股数,SUMIF(交易记录!$J$2:$J$998,_xlpm.当前日期,交易记录!$G$2:$G$998),_xlpm.盈利,SUMIF(交易记录!$J$2:$J$998,_xlpm.当前日期,交易记录!$I$2:$I$998),_xlpm.买入文本,IF(_xlpm.买入次数>0,"买入"&_xlpm.买入次数&"次，共"&_xlpm.买入股数&"股",""),_xlpm.卖出文本,IF(_xlpm.卖出次数>0,"卖出"&_xlpm.卖出次数&"次，共"&_xlpm.卖出股数&"股",""),_xlpm.盈利文本,IF(_xlpm.盈利>0,"实现盈利"&TEXT(_xlpm.盈利,"0.00")&"元",""),_xlpm.结果,_xlfn.TEXTJOIN(CHAR(10),TRUE,_xlpm.买入文本,_xlpm.卖出文本,_xlpm.盈利文本),IF(_xlpm.结果="","",_xlpm.结果)) | E6: =_xlfn.LET(_xlpm.当前日期,DATE($A$1,E$1,$A6),_xlpm.买入次数,COUNTIF(交易记录!$B$2:$B$998,_xlpm.当前日期),_xlpm.买入股数,SUMIF(交易记录!$B$2:$B$998,_xlpm.当前日期,交易记录!$D$2:$D$998),_xlpm.卖出次数,COUNTIF(交易记录!$J$2:$J$998,_xlpm.当前日期),_xlpm.卖出股数,SUMIF(交易记录!$J$2:$J$998,_xlpm.当前日期,交易记录!$G$2:$G$998),_xlpm.盈利,SUMIF(交易记录!$J$2:$J$998,_xlpm.当前日期,交易记录!$I$2:$I$998),_xlpm.买入文本,IF(_xlpm.买入次数>0,"买入"&_xlpm.买入次数&"次，共"&_xlpm.买入股数&"股",""),_xlpm.卖出文本,IF(_xlpm.卖出次数>0,"卖出"&_xlpm.卖出次数&"次，共"&_xlpm.卖出股数&"股",""),_xlpm.盈利文本,IF(_xlpm.盈利>0,"实现盈利"&TEXT(_xlpm.盈利,"0.00")&"元",""),_xlpm.结果,_xlfn.TEXTJOIN(CHAR(10),TRUE,_xlpm.买入文本,_xlpm.卖出文本,_xlpm.盈利文本),IF(_xlpm.结果="","",_xlpm.结果)) | F6: =_xlfn.LET(_xlpm.当前日期,DATE($A$1,F$1,$A6),_xlpm.买入次数,COUNTIF(交易记录!$B$2:$B$998,_xlpm.当前日期),_xlpm.买入股数,SUMIF(交易记录!$B$2:$B$998,_xlpm.当前日期,交易记录!$D$2:$D$998),_xlpm.卖出次数,COUNTIF(交易记录!$J$2:$J$998,_xlpm.当前日期),_xlpm.卖出股数,SUMIF(交易记录!$J$2:$J$998,_xlpm.当前日期,交易记录!$G$2:$G$998),_xlpm.盈利,SUMIF(交易记录!$J$2:$J$998,_xlpm.当前日期,交易记录!$I$2:$I$998),_xlpm.买入文本,IF(_xlpm.买入次数>0,"买入"&_xlpm.买入次数&"次，共"&_xlpm.买入股数&"股",""),_xlpm.卖出文本,IF(_xlpm.卖出次数>0,"卖出"&_xlpm.卖出次数&"次，共"&_xlpm.卖出股数&"股",""),_xlpm.盈利文本,IF(_xlpm.盈利>0,"实现盈利"&TEXT(_xlpm.盈利,"0.00")&"元",""),_xlpm.结果,_xlfn.TEXTJOIN(CHAR(10),TRUE,_xlpm.买入文本,_xlpm.卖出文本,_xlpm.盈利文本),IF(_xlpm.结果="","",_xlpm.结果)) | G6: =_xlfn.LET(_xlpm.当前日期,DATE($A$1,G$1,$A6),_xlpm.买入次数,COUNTIF(交易记录!$B$2:$B$998,_xlpm.当前日期),_xlpm.买入股数,SUMIF(交易记录!$B$2:$B$998,_xlpm.当前日期,交易记录!$D$2:$D$998),_xlpm.卖出次数,COUNTIF(交易记录!$J$2:$J$998,_xlpm.当前日期),_xlpm.卖出股数,SUMIF(交易记录!$J$2:$J$998,_xlpm.当前日期,交易记录!$G$2:$G$998),_xlpm.盈利,SUMIF(交易记录!$J$2:$J$998,_xlpm.当前日期,交易记录!$I$2:$I$998),_xlpm.买入文本,IF(_xlpm.买入次数>0,"买入"&_xlpm.买入次数&"次，共"&_xlpm.买入股数&"股",""),_xlpm.卖出文本,IF(_xlpm.卖出次数>0,"卖出"&_xlpm.卖出次数&"次，共"&_xlpm.卖出股数&"股",""),_xlpm.盈利文本,IF(_xlpm.盈利>0,"实现盈利"&TEXT(_xlpm.盈利,"0.00")&"元",""),_xlpm.结果,_xlfn.TEXTJOIN(CHAR(10),TRUE,_xlpm.买入文本,_xlpm.卖出文本,_xlpm.盈利文本),IF(_xlpm.结果="","",_xlpm.结果)) | H6: =_xlfn.LET(_xlpm.当前日期,DATE($A$1,H$1,$A6),_xlpm.买入次数,COUNTIF(交易记录!$B$2:$B$998,_xlpm.当前日期),_xlpm.买入股数,SUMIF(交易记录!$B$2:$B$998,_xlpm.当前日期,交易记录!$D$2:$D$998),_xlpm.卖出次数,COUNTIF(交易记录!$J$2:$J$998,_xlpm.当前日期),_xlpm.卖出股数,SUMIF(交易记录!$J$2:$J$998,_xlpm.当前日期,交易记录!$G$2:$G$998),_xlpm.盈利,SUMIF(交易记录!$J$2:$J$998,_xlpm.当前日期,交易记录!$I$2:$I$998),_xlpm.买入文本,IF(_xlpm.买入次数>0,"买入"&_xlpm.买入次数&"次，共"&_xlpm.买入股数&"股",""),_xlpm.卖出文本,IF(_xlpm.卖出次数>0,"卖出"&_xlpm.卖出次数&"次，共"&_xlpm.卖出股数&"股",""),_xlpm.盈利文本,IF(_xlpm.盈利>0,"实现盈利"&TEXT(_xlpm.盈利,"0.00")&"元",""),_xlpm.结果,_xlfn.TEXTJOIN(CHAR(10),TRUE,_xlpm.买入文本,_xlpm.卖出文本,_xlpm.盈利文本),IF(_xlpm.结果="","",_xlpm.结果)) | I6: =_xlfn.LET(_xlpm.当前日期,DATE($A$1,I$1,$A6),_xlpm.买入次数,COUNTIF(交易记录!$B$2:$B$998,_xlpm.当前日期),_xlpm.买入股数,SUMIF(交易记录!$B$2:$B$998,_xlpm.当前日期,交易记录!$D$2:$D$998),_xlpm.卖出次数,COUNTIF(交易记录!$J$2:$J$998,_xlpm.当前日期),_xlpm.卖出股数,SUMIF(交易记录!$J$2:$J$998,_xlpm.当前日期,交易记录!$G$2:$G$998),_xlpm.盈利,SUMIF(交易记录!$J$2:$J$998,_xlpm.当前日期,交易记录!$I$2:$I$998),_xlpm.买入文本,IF(_xlpm.买入次数>0,"买入"&_xlpm.买入次数&"次，共"&_xlpm.买入股数&"股",""),_xlpm.卖出文本,IF(_xlpm.卖出次数>0,"卖出"&_xlpm.卖出次数&"次，共"&_xlpm.卖出股数&"股",""),_xlpm.盈利文本,IF(_xlpm.盈利>0,"实现盈利"&TEXT(_xlpm.盈利,"0.00")&"元",""),_xlpm.结果,_xlfn.TEXTJOIN(CHAR(10),TRUE,_xlpm.买入文本,_xlpm.卖出文本,_xlpm.盈利文本),IF(_xlpm.结果="","",_xlpm.结果)) | ... M6: =_xlfn.LET(_xlpm.当前日期,DATE($A$1,M$1,$A6),_xlpm.买入次数,COUNTIF(交易记录!$B$2:$B$998,_xlpm.当前日期),_xlpm.买入股数,SUMIF(交易记录!$B$2:$B$998,_xlpm.当前日期,交易记录!$D$2:$D$998),_xlpm.卖出次数,COUNTIF(交易记录!$J$2:$J$998,_xlpm.当前日期),_xlpm.卖出股数,SUMIF(交易记录!$J$2:$J$998,_xlpm.当前日期,交易记录!$G$2:$G$998),_xlpm.盈利,SUMIF(交易记录!$J$2:$J$998,_xlpm.当前日期,交易记录!$I$2:$I$998),_xlpm.买入文本,IF(_xlpm.买入次数>0,"买入"&_xlpm.买入次数&"次，共"&_xlpm.买入股数&"股",""),_xlpm.卖出文本,IF(_xlpm.卖出次数>0,"卖出"&_xlpm.卖出次数&"次，共"&_xlpm.卖出股数&"股",""),_xlpm.盈利文本,IF(_xlpm.盈利>0,"实现盈利"&TEXT(_xlpm.盈利,"0.00")&"元",""),_xlpm.结果,_xlfn.TEXTJOIN(CHAR(10),TRUE,_xlpm.买入文本,_xlpm.卖出文本,_xlpm.盈利文本),IF(_xlpm.结果="","",_xlpm.结果))
A7: 6 | B7: =_xlfn.LET(_xlpm.当前日期,DATE($A$1,B$1,$A7),_xlpm.买入次数,COUNTIF(交易记录!$B$2:$B$998,_xlpm.当前日期),_xlpm.买入股数,SUMIF(交易记录!$B$2:$B$998,_xlpm.当前日期,交易记录!$D$2:$D$998),_xlpm.卖出次数,COUNTIF(交易记录!$J$2:$J$998,_xlpm.当前日期),_xlpm.卖出股数,SUMIF(交易记录!$J$2:$J$998,_xlpm.当前日期,交易记录!$G$2:$G$998),_xlpm.盈利,SUMIF(交易记录!$J$2:$J$998,_xlpm.当前日期,交易记录!$I$2:$I$998),_xlpm.买入文本,IF(_xlpm.买入次数>0,"买入"&_xlpm.买入次数&"次，共"&_xlpm.买入股数&"股",""),_xlpm.卖出文本,IF(_xlpm.卖出次数>0,"卖出"&_xlpm.卖出次数&"次，共"&_xlpm.卖出股数&"股",""),_xlpm.盈利文本,IF(_xlpm.盈利>0,"实现盈利"&TEXT(_xlpm.盈利,"0.00")&"元",""),_xlpm.结果,_xlfn.TEXTJOIN(CHAR(10),TRUE,_xlpm.买入文本,_xlpm.卖出文本,_xlpm.盈利文本),IF(_xlpm.结果="","",_xlpm.结果)) | C7: =_xlfn.LET(_xlpm.当前日期,DATE($A$1,C$1,$A7),_xlpm.买入次数,COUNTIF(交易记录!$B$2:$B$998,_xlpm.当前日期),_xlpm.买入股数,SUMIF(交易记录!$B$2:$B$998,_xlpm.当前日期,交易记录!$D$2:$D$998),_xlpm.卖出次数,COUNTIF(交易记录!$J$2:$J$998,_xlpm.当前日期),_xlpm.卖出股数,SUMIF(交易记录!$J$2:$J$998,_xlpm.当前日期,交易记录!$G$2:$G$998),_xlpm.盈利,SUMIF(交易记录!$J$2:$J$998,_xlpm.当前日期,交易记录!$I$2:$I$998),_xlpm.买入文本,IF(_xlpm.买入次数>0,"买入"&_xlpm.买入次数&"次，共"&_xlpm.买入股数&"股",""),_xlpm.卖出文本,IF(_xlpm.卖出次数>0,"卖出"&_xlpm.卖出次数&"次，共"&_xlpm.卖出股数&"股",""),_xlpm.盈利文本,IF(_xlpm.盈利>0,"实现盈利"&TEXT(_xlpm.盈利,"0.00")&"元",""),_xlpm.结果,_xlfn.TEXTJOIN(CHAR(10),TRUE,_xlpm.买入文本,_xlpm.卖出文本,_xlpm.盈利文本),IF(_xlpm.结果="","",_xlpm.结果)) | D7: =_xlfn.LET(_xlpm.当前日期,DATE($A$1,D$1,$A7),_xlpm.买入次数,COUNTIF(交易记录!$B$2:$B$998,_xlpm.当前日期),_xlpm.买入股数,SUMIF(交易记录!$B$2:$B$998,_xlpm.当前日期,交易记录!$D$2:$D$998),_xlpm.卖出次数,COUNTIF(交易记录!$J$2:$J$998,_xlpm.当前日期),_xlpm.卖出股数,SUMIF(交易记录!$J$2:$J$998,_xlpm.当前日期,交易记录!$G$2:$G$998),_xlpm.盈利,SUMIF(交易记录!$J$2:$J$998,_xlpm.当前日期,交易记录!$I$2:$I$998),_xlpm.买入文本,IF(_xlpm.买入次数>0,"买入"&_xlpm.买入次数&"次，共"&_xlpm.买入股数&"股",""),_xlpm.卖出文本,IF(_xlpm.卖出次数>0,"卖出"&_xlpm.卖出次数&"次，共"&_xlpm.卖出股数&"股",""),_xlpm.盈利文本,IF(_xlpm.盈利>0,"实现盈利"&TEXT(_xlpm.盈利,"0.00")&"元",""),_xlpm.结果,_xlfn.TEXTJOIN(CHAR(10),TRUE,_xlpm.买入文本,_xlpm.卖出文本,_xlpm.盈利文本),IF(_xlpm.结果="","",_xlpm.结果)) | E7: =_xlfn.LET(_xlpm.当前日期,DATE($A$1,E$1,$A7),_xlpm.买入次数,COUNTIF(交易记录!$B$2:$B$998,_xlpm.当前日期),_xlpm.买入股数,SUMIF(交易记录!$B$2:$B$998,_xlpm.当前日期,交易记录!$D$2:$D$998),_xlpm.卖出次数,COUNTIF(交易记录!$J$2:$J$998,_xlpm.当前日期),_xlpm.卖出股数,SUMIF(交易记录!$J$2:$J$998,_xlpm.当前日期,交易记录!$G$2:$G$998),_xlpm.盈利,SUMIF(交易记录!$J$2:$J$998,_xlpm.当前日期,交易记录!$I$2:$I$998),_xlpm.买入文本,IF(_xlpm.买入次数>0,"买入"&_xlpm.买入次数&"次，共"&_xlpm.买入股数&"股",""),_xlpm.卖出文本,IF(_xlpm.卖出次数>0,"卖出"&_xlpm.卖出次数&"次，共"&_xlpm.卖出股数&"股",""),_xlpm.盈利文本,IF(_xlpm.盈利>0,"实现盈利"&TEXT(_xlpm.盈利,"0.00")&"元",""),_xlpm.结果,_xlfn.TEXTJOIN(CHAR(10),TRUE,_xlpm.买入文本,_xlpm.卖出文本,_xlpm.盈利文本),IF(_xlpm.结果="","",_xlpm.结果)) | F7: =_xlfn.LET(_xlpm.当前日期,DATE($A$1,F$1,$A7),_xlpm.买入次数,COUNTIF(交易记录!$B$2:$B$998,_xlpm.当前日期),_xlpm.买入股数,SUMIF(交易记录!$B$2:$B$998,_xlpm.当前日期,交易记录!$D$2:$D$998),_xlpm.卖出次数,COUNTIF(交易记录!$J$2:$J$998,_xlpm.当前日期),_xlpm.卖出股数,SUMIF(交易记录!$J$2:$J$998,_xlpm.当前日期,交易记录!$G$2:$G$998),_xlpm.盈利,SUMIF(交易记录!$J$2:$J$998,_xlpm.当前日期,交易记录!$I$2:$I$998),_xlpm.买入文本,IF(_xlpm.买入次数>0,"买入"&_xlpm.买入次数&"次，共"&_xlpm.买入股数&"股",""),_xlpm.卖出文本,IF(_xlpm.卖出次数>0,"卖出"&_xlpm.卖出次数&"次，共"&_xlpm.卖出股数&"股",""),_xlpm.盈利文本,IF(_xlpm.盈利>0,"实现盈利"&TEXT(_xlpm.盈利,"0.00")&"元",""),_xlpm.结果,_xlfn.TEXTJOIN(CHAR(10),TRUE,_xlpm.买入文本,_xlpm.卖出文本,_xlpm.盈利文本),IF(_xlpm.结果="","",_xlpm.结果)) | G7: =_xlfn.LET(_xlpm.当前日期,DATE($A$1,G$1,$A7),_xlpm.买入次数,COUNTIF(交易记录!$B$2:$B$998,_xlpm.当前日期),_xlpm.买入股数,SUMIF(交易记录!$B$2:$B$998,_xlpm.当前日期,交易记录!$D$2:$D$998),_xlpm.卖出次数,COUNTIF(交易记录!$J$2:$J$998,_xlpm.当前日期),_xlpm.卖出股数,SUMIF(交易记录!$J$2:$J$998,_xlpm.当前日期,交易记录!$G$2:$G$998),_xlpm.盈利,SUMIF(交易记录!$J$2:$J$998,_xlpm.当前日期,交易记录!$I$2:$I$998),_xlpm.买入文本,IF(_xlpm.买入次数>0,"买入"&_xlpm.买入次数&"次，共"&_xlpm.买入股数&"股",""),_xlpm.卖出文本,IF(_xlpm.卖出次数>0,"卖出"&_xlpm.卖出次数&"次，共"&_xlpm.卖出股数&"股",""),_xlpm.盈利文本,IF(_xlpm.盈利>0,"实现盈利"&TEXT(_xlpm.盈利,"0.00")&"元",""),_xlpm.结果,_xlfn.TEXTJOIN(CHAR(10),TRUE,_xlpm.买入文本,_xlpm.卖出文本,_xlpm.盈利文本),IF(_xlpm.结果="","",_xlpm.结果)) | H7: =_xlfn.LET(_xlpm.当前日期,DATE($A$1,H$1,$A7),_xlpm.买入次数,COUNTIF(交易记录!$B$2:$B$998,_xlpm.当前日期),_xlpm.买入股数,SUMIF(交易记录!$B$2:$B$998,_xlpm.当前日期,交易记录!$D$2:$D$998),_xlpm.卖出次数,COUNTIF(交易记录!$J$2:$J$998,_xlpm.当前日期),_xlpm.卖出股数,SUMIF(交易记录!$J$2:$J$998,_xlpm.当前日期,交易记录!$G$2:$G$998),_xlpm.盈利,SUMIF(交易记录!$J$2:$J$998,_xlpm.当前日期,交易记录!$I$2:$I$998),_xlpm.买入文本,IF(_xlpm.买入次数>0,"买入"&_xlpm.买入次数&"次，共"&_xlpm.买入股数&"股",""),_xlpm.卖出文本,IF(_xlpm.卖出次数>0,"卖出"&_xlpm.卖出次数&"次，共"&_xlpm.卖出股数&"股",""),_xlpm.盈利文本,IF(_xlpm.盈利>0,"实现盈利"&TEXT(_xlpm.盈利,"0.00")&"元",""),_xlpm.结果,_xlfn.TEXTJOIN(CHAR(10),TRUE,_xlpm.买入文本,_xlpm.卖出文本,_xlpm.盈利文本),IF(_xlpm.结果="","",_xlpm.结果)) | I7: =_xlfn.LET(_xlpm.当前日期,DATE($A$1,I$1,$A7),_xlpm.买入次数,COUNTIF(交易记录!$B$2:$B$998,_xlpm.当前日期),_xlpm.买入股数,SUMIF(交易记录!$B$2:$B$998,_xlpm.当前日期,交易记录!$D$2:$D$998),_xlpm.卖出次数,COUNTIF(交易记录!$J$2:$J$998,_xlpm.当前日期),_xlpm.卖出股数,SUMIF(交易记录!$J$2:$J$998,_xlpm.当前日期,交易记录!$G$2:$G$998),_xlpm.盈利,SUMIF(交易记录!$J$2:$J$998,_xlpm.当前日期,交易记录!$I$2:$I$998),_xlpm.买入文本,IF(_xlpm.买入次数>0,"买入"&_xlpm.买入次数&"次，共"&_xlpm.买入股数&"股",""),_xlpm.卖出文本,IF(_xlpm.卖出次数>0,"卖出"&_xlpm.卖出次数&"次，共"&_xlpm.卖出股数&"股",""),_xlpm.盈利文本,IF(_xlpm.盈利>0,"实现盈利"&TEXT(_xlpm.盈利,"0.00")&"元",""),_xlpm.结果,_xlfn.TEXTJOIN(CHAR(10),TRUE,_xlpm.买入文本,_xlpm.卖出文本,_xlpm.盈利文本),IF(_xlpm.结果="","",_xlpm.结果)) | ... M7: =_xlfn.LET(_xlpm.当前日期,DATE($A$1,M$1,$A7),_xlpm.买入次数,COUNTIF(交易记录!$B$2:$B$998,_xlpm.当前日期),_xlpm.买入股数,SUMIF(交易记录!$B$2:$B$998,_xlpm.当前日期,交易记录!$D$2:$D$998),_xlpm.卖出次数,COUNTIF(交易记录!$J$2:$J$998,_xlpm.当前日期),_xlpm.卖出股数,SUMIF(交易记录!$J$2:$J$998,_xlpm.当前日期,交易记录!$G$2:$G$998),_xlpm.盈利,SUMIF(交易记录!$J$2:$J$998,_xlpm.当前日期,交易记录!$I$2:$I$998),_xlpm.买入文本,IF(_xlpm.买入次数>0,"买入"&_xlpm.买入次数&"次，共"&_xlpm.买入股数&"股",""),_xlpm.卖出文本,IF(_xlpm.卖出次数>0,"卖出"&_xlpm.卖出次数&"次，共"&_xlpm.卖出股数&"股",""),_xlpm.盈利文本,IF(_xlpm.盈利>0,"实现盈利"&TEXT(_xlpm.盈利,"0.00")&"元",""),_xlpm.结果,_xlfn.TEXTJOIN(CHAR(10),TRUE,_xlpm.买入文本,_xlpm.卖出文本,_xlpm.盈利文本),IF(_xlpm.结果="","",_xlpm.结果))
A8: 7 | B8: =_xlfn.LET(_xlpm.当前日期,DATE($A$1,B$1,$A8),_xlpm.买入次数,COUNTIF(交易记录!$B$2:$B$998,_xlpm.当前日期),_xlpm.买入股数,SUMIF(交易记录!$B$2:$B$998,_xlpm.当前日期,交易记录!$D$2:$D$998),_xlpm.卖出次数,COUNTIF(交易记录!$J$2:$J$998,_xlpm.当前日期),_xlpm.卖出股数,SUMIF(交易记录!$J$2:$J$998,_xlpm.当前日期,交易记录!$G$2:$G$998),_xlpm.盈利,SUMIF(交易记录!$J$2:$J$998,_xlpm.当前日期,交易记录!$I$2:$I$998),_xlpm.买入文本,IF(_xlpm.买入次数>0,"买入"&_xlpm.买入次数&"次，共"&_xlpm.买入股数&"股",""),_xlpm.卖出文本,IF(_xlpm.卖出次数>0,"卖出"&_xlpm.卖出次数&"次，共"&_xlpm.卖出股数&"股",""),_xlpm.盈利文本,IF(_xlpm.盈利>0,"实现盈利"&TEXT(_xlpm.盈利,"0.00")&"元",""),_xlpm.结果,_xlfn.TEXTJOIN(CHAR(10),TRUE,_xlpm.买入文本,_xlpm.卖出文本,_xlpm.盈利文本),IF(_xlpm.结果="","",_xlpm.结果)) | C8: =_xlfn.LET(_xlpm.当前日期,DATE($A$1,C$1,$A8),_xlpm.买入次数,COUNTIF(交易记录!$B$2:$B$998,_xlpm.当前日期),_xlpm.买入股数,SUMIF(交易记录!$B$2:$B$998,_xlpm.当前日期,交易记录!$D$2:$D$998),_xlpm.卖出次数,COUNTIF(交易记录!$J$2:$J$998,_xlpm.当前日期),_xlpm.卖出股数,SUMIF(交易记录!$J$2:$J$998,_xlpm.当前日期,交易记录!$G$2:$G$998),_xlpm.盈利,SUMIF(交易记录!$J$2:$J$998,_xlpm.当前日期,交易记录!$I$2:$I$998),_xlpm.买入文本,IF(_xlpm.买入次数>0,"买入"&_xlpm.买入次数&"次，共"&_xlpm.买入股数&"股",""),_xlpm.卖出文本,IF(_xlpm.卖出次数>0,"卖出"&_xlpm.卖出次数&"次，共"&_xlpm.卖出股数&"股",""),_xlpm.盈利文本,IF(_xlpm.盈利>0,"实现盈利"&TEXT(_xlpm.盈利,"0.00")&"元",""),_xlpm.结果,_xlfn.TEXTJOIN(CHAR(10),TRUE,_xlpm.买入文本,_xlpm.卖出文本,_xlpm.盈利文本),IF(_xlpm.结果="","",_xlpm.结果)) | D8: =_xlfn.LET(_xlpm.当前日期,DATE($A$1,D$1,$A8),_xlpm.买入次数,COUNTIF(交易记录!$B$2:$B$998,_xlpm.当前日期),_xlpm.买入股数,SUMIF(交易记录!$B$2:$B$998,_xlpm.当前日期,交易记录!$D$2:$D$998),_xlpm.卖出次数,COUNTIF(交易记录!$J$2:$J$998,_xlpm.当前日期),_xlpm.卖出股数,SUMIF(交易记录!$J$2:$J$998,_xlpm.当前日期,交易记录!$G$2:$G$998),_xlpm.盈利,SUMIF(交易记录!$J$2:$J$998,_xlpm.当前日期,交易记录!$I$2:$I$998),_xlpm.买入文本,IF(_xlpm.买入次数>0,"买入"&_xlpm.买入次数&"次，共"&_xlpm.买入股数&"股",""),_xlpm.卖出文本,IF(_xlpm.卖出次数>0,"卖出"&_xlpm.卖出次数&"次，共"&_xlpm.卖出股数&"股",""),_xlpm.盈利文本,IF(_xlpm.盈利>0,"实现盈利"&TEXT(_xlpm.盈利,"0.00")&"元",""),_xlpm.结果,_xlfn.TEXTJOIN(CHAR(10),TRUE,_xlpm.买入文本,_xlpm.卖出文本,_xlpm.盈利文本),IF(_xlpm.结果="","",_xlpm.结果)) | E8: =_xlfn.LET(_xlpm.当前日期,DATE($A$1,E$1,$A8),_xlpm.买入次数,COUNTIF(交易记录!$B$2:$B$998,_xlpm.当前日期),_xlpm.买入股数,SUMIF(交易记录!$B$2:$B$998,_xlpm.当前日期,交易记录!$D$2:$D$998),_xlpm.卖出次数,COUNTIF(交易记录!$J$2:$J$998,_xlpm.当前日期),_xlpm.卖出股数,SUMIF(交易记录!$J$2:$J$998,_xlpm.当前日期,交易记录!$G$2:$G$998),_xlpm.盈利,SUMIF(交易记录!$J$2:$J$998,_xlpm.当前日期,交易记录!$I$2:$I$998),_xlpm.买入文本,IF(_xlpm.买入次数>0,"买入"&_xlpm.买入次数&"次，共"&_xlpm.买入股数&"股",""),_xlpm.卖出文本,IF(_xlpm.卖出次数>0,"卖出"&_xlpm.卖出次数&"次，共"&_xlpm.卖出股数&"股",""),_xlpm.盈利文本,IF(_xlpm.盈利>0,"实现盈利"&TEXT(_xlpm.盈利,"0.00")&"元",""),_xlpm.结果,_xlfn.TEXTJOIN(CHAR(10),TRUE,_xlpm.买入文本,_xlpm.卖出文本,_xlpm.盈利文本),IF(_xlpm.结果="","",_xlpm.结果)) | F8: =_xlfn.LET(_xlpm.当前日期,DATE($A$1,F$1,$A8),_xlpm.买入次数,COUNTIF(交易记录!$B$2:$B$998,_xlpm.当前日期),_xlpm.买入股数,SUMIF(交易记录!$B$2:$B$998,_xlpm.当前日期,交易记录!$D$2:$D$998),_xlpm.卖出次数,COUNTIF(交易记录!$J$2:$J$998,_xlpm.当前日期),_xlpm.卖出股数,SUMIF(交易记录!$J$2:$J$998,_xlpm.当前日期,交易记录!$G$2:$G$998),_xlpm.盈利,SUMIF(交易记录!$J$2:$J$998,_xlpm.当前日期,交易记录!$I$2:$I$998),_xlpm.买入文本,IF(_xlpm.买入次数>0,"买入"&_xlpm.买入次数&"次，共"&_xlpm.买入股数&"股",""),_xlpm.卖出文本,IF(_xlpm.卖出次数>0,"卖出"&_xlpm.卖出次数&"次，共"&_xlpm.卖出股数&"股",""),_xlpm.盈利文本,IF(_xlpm.盈利>0,"实现盈利"&TEXT(_xlpm.盈利,"0.00")&"元",""),_xlpm.结果,_xlfn.TEXTJOIN(CHAR(10),TRUE,_xlpm.买入文本,_xlpm.卖出文本,_xlpm.盈利文本),IF(_xlpm.结果="","",_xlpm.结果)) | G8: =_xlfn.LET(_xlpm.当前日期,DATE($A$1,G$1,$A8),_xlpm.买入次数,COUNTIF(交易记录!$B$2:$B$998,_xlpm.当前日期),_xlpm.买入股数,SUMIF(交易记录!$B$2:$B$998,_xlpm.当前日期,交易记录!$D$2:$D$998),_xlpm.卖出次数,COUNTIF(交易记录!$J$2:$J$998,_xlpm.当前日期),_xlpm.卖出股数,SUMIF(交易记录!$J$2:$J$998,_xlpm.当前日期,交易记录!$G$2:$G$998),_xlpm.盈利,SUMIF(交易记录!$J$2:$J$998,_xlpm.当前日期,交易记录!$I$2:$I$998),_xlpm.买入文本,IF(_xlpm.买入次数>0,"买入"&_xlpm.买入次数&"次，共"&_xlpm.买入股数&"股",""),_xlpm.卖出文本,IF(_xlpm.卖出次数>0,"卖出"&_xlpm.卖出次数&"次，共"&_xlpm.卖出股数&"股",""),_xlpm.盈利文本,IF(_xlpm.盈利>0,"实现盈利"&TEXT(_xlpm.盈利,"0.00")&"元",""),_xlpm.结果,_xlfn.TEXTJOIN(CHAR(10),TRUE,_xlpm.买入文本,_xlpm.卖出文本,_xlpm.盈利文本),IF(_xlpm.结果="","",_xlpm.结果)) | H8: =_xlfn.LET(_xlpm.当前日期,DATE($A$1,H$1,$A8),_xlpm.买入次数,COUNTIF(交易记录!$B$2:$B$998,_xlpm.当前日期),_xlpm.买入股数,SUMIF(交易记录!$B$2:$B$998,_xlpm.当前日期,交易记录!$D$2:$D$998),_xlpm.卖出次数,COUNTIF(交易记录!$J$2:$J$998,_xlpm.当前日期),_xlpm.卖出股数,SUMIF(交易记录!$J$2:$J$998,_xlpm.当前日期,交易记录!$G$2:$G$998),_xlpm.盈利,SUMIF(交易记录!$J$2:$J$998,_xlpm.当前日期,交易记录!$I$2:$I$998),_xlpm.买入文本,IF(_xlpm.买入次数>0,"买入"&_xlpm.买入次数&"次，共"&_xlpm.买入股数&"股",""),_xlpm.卖出文本,IF(_xlpm.卖出次数>0,"卖出"&_xlpm.卖出次数&"次，共"&_xlpm.卖出股数&"股",""),_xlpm.盈利文本,IF(_xlpm.盈利>0,"实现盈利"&TEXT(_xlpm.盈利,"0.00")&"元",""),_xlpm.结果,_xlfn.TEXTJOIN(CHAR(10),TRUE,_xlpm.买入文本,_xlpm.卖出文本,_xlpm.盈利文本),IF(_xlpm.结果="","",_xlpm.结果)) | I8: =_xlfn.LET(_xlpm.当前日期,DATE($A$1,I$1,$A8),_xlpm.买入次数,COUNTIF(交易记录!$B$2:$B$998,_xlpm.当前日期),_xlpm.买入股数,SUMIF(交易记录!$B$2:$B$998,_xlpm.当前日期,交易记录!$D$2:$D$998),_xlpm.卖出次数,COUNTIF(交易记录!$J$2:$J$998,_xlpm.当前日期),_xlpm.卖出股数,SUMIF(交易记录!$J$2:$J$998,_xlpm.当前日期,交易记录!$G$2:$G$998),_xlpm.盈利,SUMIF(交易记录!$J$2:$J$998,_xlpm.当前日期,交易记录!$I$2:$I$998),_xlpm.买入文本,IF(_xlpm.买入次数>0,"买入"&_xlpm.买入次数&"次，共"&_xlpm.买入股数&"股",""),_xlpm.卖出文本,IF(_xlpm.卖出次数>0,"卖出"&_xlpm.卖出次数&"次，共"&_xlpm.卖出股数&"股",""),_xlpm.盈利文本,IF(_xlpm.盈利>0,"实现盈利"&TEXT(_xlpm.盈利,"0.00")&"元",""),_xlpm.结果,_xlfn.TEXTJOIN(CHAR(10),TRUE,_xlpm.买入文本,_xlpm.卖出文本,_xlpm.盈利文本),IF(_xlpm.结果="","",_xlpm.结果)) | ... M8: =_xlfn.LET(_xlpm.当前日期,DATE($A$1,M$1,$A8),_xlpm.买入次数,COUNTIF(交易记录!$B$2:$B$998,_xlpm.当前日期),_xlpm.买入股数,SUMIF(交易记录!$B$2:$B$998,_xlpm.当前日期,交易记录!$D$2:$D$998),_xlpm.卖出次数,COUNTIF(交易记录!$J$2:$J$998,_xlpm.当前日期),_xlpm.卖出股数,SUMIF(交易记录!$J$2:$J$998,_xlpm.当前日期,交易记录!$G$2:$G$998),_xlpm.盈利,SUMIF(交易记录!$J$2:$J$998,_xlpm.当前日期,交易记录!$I$2:$I$998),_xlpm.买入文本,IF(_xlpm.买入次数>0,"买入"&_xlpm.买入次数&"次，共"&_xlpm.买入股数&"股",""),_xlpm.卖出文本,IF(_xlpm.卖出次数>0,"卖出"&_xlpm.卖出次数&"次，共"&_xlpm.卖出股数&"股",""),_xlpm.盈利文本,IF(_xlpm.盈利>0,"实现盈利"&TEXT(_xlpm.盈利,"0.00")&"元",""),_xlpm.结果,_xlfn.TEXTJOIN(CHAR(10),TRUE,_xlpm.买入文本,_xlpm.卖出文本,_xlpm.盈利文本),IF(_xlpm.结果="","",_xlpm.结果))
